Workbook

Sheet SETEMBRO
C4: GESTÃO A VISTA DO RESULTADO DURANTE O MÊS VIGENTE
C6: QTD | D6: VEICULO | E6: META MÊS | G6: PRODUÇÃO
C7: 4 | D7: LS | E7: 70000 | G7: =E7*C7 -> 280000
C8: 27 | D8: RODOTREM | E8: 100000 | G8: =E8*C8 -> 2700000
E9: TOTAL | G9: =SUM(G7:G8) -> 2980000
G11: DIGITAR
C12: DIA | D12: MEDIA DIA | E12: ACUMULADO POR MEDIA | F12: DIA | G12: Faturado dia | H12: acumulado mês | I12: META 3.000.000 | J12: PROJEÇAO | K12: DIFERENÇA DA META | L12: COMPARATIVO COM META | M12: COMISSÃO
C13: 45901 | D13: =AVERAGE(G13) -> 68867.22 | E13: =D13*30 -> 2066016.6 | F13: 45901 | G13: =PRODUÇAO!H37 -> 68867.22 | H13: =G13 -> 68867.22 | I13: =H13/3000000 -> 0.02295574 | J13: =H13*30 -> 2066016.6 | K13: =J13-3000000 -> -933983.4 | L13: =J13/3000000 -> 0.6886722 | M13: =G13*8.5% -> 5853.7137
C14: 45902 | D14: =AVERAGE(G13:G14) -> 110105.35 | E14: =D14*30 -> 3303160.5 | F14: 45902 | G14: =PRODUÇAO!I37 -> 151343.48 | H14: =H13+G14 -> 220210.7 | I14: =H14/3000000 -> 0.073403567 | J14: =H14/2*30 -> 3303160.5 | K14: =J14-3000000 -> 303160.5 | L14: =J14/3000000 -> 1.1010535 | M14: =G14*8.5% -> 12864.196
C15: 45903 | D15: =AVERAGE(G13:G15) -> 101606.71 | E15: =D15*30 -> 3048201.2 | F15: 45903 | G15: =PRODUÇAO!J37 -> 84609.42 | H15: =H14+G15 -> 304820.12 | I15: =H15/3000000 -> 0.10160671 | J15: =H15/3*30 -> 3048201.2 | K15: =J15-3000000 -> 48201.2 | L15: =J15/3000000 -> 1.0160671 | M15: =G15*8.5% -> 7191.8007
C16: 45904 | D16: =AVERAGE(G13:G16) -> 97246.03 | E16: =D16*30 -> 2917380.9 | F16: 45904 | G16: =PRODUÇAO!K37 -> 84164 | H16: =H15+G16 -> 388984.12 | I16: =H16/3000000 -> 0.12966137 | J16: =H16/4*30 -> 2917380.9 | K16: =J16-3000000 -> -82619.1 | L16: =J16/3000000 -> 0.9724603 | M16: =G16*8.5% -> 7153.94
C17: 45905 | D17: =AVERAGE(G13:G17) -> 117289.43 | E17: =D17*30 -> 3518683 | F17: 45905 | G17: =PRODUÇAO!L37 -> 197463.04 | H17: =H16+G17 -> 586447.16 | I17: =H17/3000000 -> 0.19548239 | J17: =H17/5*30 -> 3518683 | K17: =J17-3000000 -> 518682.97 | L17: =J17/3000000 -> 1.1728943 | M17: =G17*8.5% -> 16784.359
C18: 45906 | D18: =AVERAGE(G13:G18) -> 108480.37 | E18: =D18*30 -> 3254411.2 | F18: 45906 | G18: =PRODUÇAO!M37 -> 64435.08 | H18: =H17+G18 -> 650882.24 | I18: =H18/3000000 -> 0.21696075 | J18: =H18/6*30 -> 3254411.2 | K18: =J18-3000000 -> 254411.21 | L18: =J18/3000000 -> 1.0848037 | M18: =G18*8.5% -> 5476.9818
C19: 45907 | D19: =AVERAGE(G13:G19) -> 92983.177 | E19: =D19*30 -> 2789495.3 | F19: 45907 | G19: =PRODUÇAO!N37 -> 0 | H19: =H18+G19 -> 650882.24 | I19: =H19/3000000 -> 0.21696075 | J19: =H19/7*30 -> 2789495.3 | K19: =J19-3000000 -> -210504.68 | L19: =J19/3000000 -> 0.92983177 | M19: =G19*8.5% -> 0
C20: 45908 | D20: =AVERAGE(G13:G20) -> 89929.393 | E20: =D20*30 -> 2697881.8 | F20: 45908 | G20: =PRODUÇAO!O37 -> 68552.9 | H20: =H19+G20 -> 719435.14 | I20: =H20/3000000 -> 0.23981171 | J20: =H20/8*30 -> 2697881.8 | K20: =J20-3000000 -> -302118.22 | L20: =J20/3000000 -> 0.89929393 | M20: =G20*8.5% -> 5826.9965
C21: 45909 | D21: =AVERAGE(G13:G21) -> 90053.336 | E21: =D21*30 -> 2701600.1 | F21: 45909 | G21: =PRODUÇAO!P37 -> 91044.88 | H21: =H20+G21 -> 810480.02 | I21: =H21/3000000 -> 0.27016001 | J21: =H21/9*30 -> 2701600.1 | K21: =J21-3000000 -> -298399.93 | L21: =J21/3000000 -> 0.90053336 | M21: =G21*8.5% -> 7738.8148
C22: 45910 | D22: =AVERAGE(G13:G22) -> 102910.09 | E22: =D22*30 -> 3087302.6 | F22: 45910 | G22: =PRODUÇAO!Q37 -> 218620.86 | H22: =H21+G22 -> 1029100.9 | I22: =H22/3000000 -> 0.34303363 | J22: =H22/10*30 -> 3087302.6 | K22: =J22-3000000 -> 87302.647 | L22: =J22/3000000 -> 1.0291009 | M22: =G22*8.5% -> 18582.773
C23: 45911 | D23: =AVERAGE(G13:G23) -> 98698.149 | E23: =D23*30 -> 2960944.5 | F23: 45911 | G23: =PRODUÇAO!R37 -> 56578.76 | H23: =H22+G23 -> 1085679.6 | I23: =H23/3000000 -> 0.36189321 | J23: =H23/11*30 -> 2960944.5 | K23: =J23-3000000 -> -39055.521 | L23: =J23/3000000 -> 0.98698149 | M23: =G23*8.5% -> 4809.1946
C24: 45912 | D24: =AVERAGE(G13:G24) -> 101855.14 | E24: =D24*30 -> 3055654.1 | F24: 45912 | G24: =PRODUÇAO!S37 -> 136582.01 | H24: =H23+G24 -> 1222261.7 | I24: =H24/3000000 -> 0.40742055 | J24: =H24/12*30 -> 3055654.1 | K24: =J24-3000000 -> 55654.131 | L24: =J24/3000000 -> 1.0185514 | M24: =G24*8.5% -> 11609.471
C25: 45913 | D25: =AVERAGE(G13:G25) -> 109065.37 | E25: =D25*30 -> 3271961.2 | F25: 45913 | G25: =PRODUÇAO!T37 -> 195588.18 | H25: =H24+G25 -> 1417849.8 | I25: =H25/3000000 -> 0.47261661 | J25: =H25/13*30 -> 3271961.2 | K25: =J25-3000000 -> 271961.15 | L25: =J25/3000000 -> 1.0906537 | M25: =G25*8.5% -> 16624.995
C26: 45914 | D26: =AVERAGE(G13:G26) -> 102966.42 | E26: =D26*30 -> 3088992.5 | F26: 45914 | G26: =PRODUÇAO!U37 -> 23680 | H26: =H25+G26 -> 1441529.8 | I26: =H26/3000000 -> 0.48050994 | J26: =H26/14*30 -> 3088992.5 | K26: =J26-3000000 -> 88992.498 | L26: =J26/3000000 -> 1.0296642 | M26: =G26*8.5% -> 2012.8
C27: 45915 | D27: =AVERAGE(G13:G27) -> 98194.563 | E27: =D27*30 -> 2945836.9 | F27: 45915 | G27: =PRODUÇAO!V37 -> 31388.62 | H27: =H26+G27 -> 1472918.5 | I27: =H27/3000000 -> 0.49097282 | J27: =H27/15*30 -> 2945836.9 | K27: =J27-3000000 -> -54163.095 | L27: =J27/3000000 -> 0.98194563 | M27: =G27*8.5% -> 2668.0327
C28: 45916 | D28: =AVERAGE(G13:G28) -> 95916.966 | E28: =D28*30 -> 2877509 | F28: 45916 | G28: =PRODUÇAO!W37 -> 61753.01 | H28: =H27+G28 -> 1534671.5 | I28: =H28/3000000 -> 0.51155715 | J28: =H28/16*30 -> 2877509 | K28: =J28-3000000 -> -122491.01 | L28: =J28/3000000 -> 0.95916966 | M28: =G28*8.5% -> 5249.0059
C29: 45917 | D29: =AVERAGE(G13:G29) -> 95721.516 | E29: =D29*30 -> 2871645.5 | F29: 45917 | G29: =PRODUÇAO!X37 -> 92594.31 | H29: =H28+G29 -> 1627265.8 | I29: =H29/3000000 -> 0.54242192 | J29: =H29/17*30 -> 2871645.5 | K29: =J29-3000000 -> -128354.52 | L29: =J29/3000000 -> 0.95721516 | M29: =G29*8.5% -> 7870.5164
C30: 45918 | D30: =AVERAGE(G13:G30) -> 97856.867 | E30: =D30*30 -> 2935706 | F30: 45918 | G30: =PRODUÇAO!Y37 -> 134157.84 | H30: =H29+G30 -> 1761423.6 | I30: =H30/3000000 -> 0.5871412 | J30: =H30/18*30 -> 2935706 | K30: =J30-3000000 -> -64293.979 | L30: =J30/3000000 -> 0.97856867 | M30: =G30*8.5% -> 11403.416
C31: 45919 | D31: =AVERAGE(G13:G31) -> 106216.67 | E31: =D31*30 -> 3186500.2 | F31: 45919 | G31: =PRODUÇAO!Z37 -> 256693.21 | H31: =H30+G31 -> 2018116.8 | I31: =H31/3000000 -> 0.67270561 | J31: =H31/19*30 -> 3186500.2 | K31: =J31-3000000 -> 186500.25 | L31: =J31/3000000 -> 1.0621667 | M31: =G31*8.5% -> 21818.923
C32: 45920 | D32: =AVERAGE(G13:G32) -> 105118.38 | E32: =D32*30 -> 3153551.5 | F32: 45920 | G32: =PRODUÇAO!AA37 -> 84250.87 | H32: =H31+G32 -> 2102367.7 | I32: =H32/3000000 -> 0.70078923 | J32: =H32/20*30 -> 3153551.5 | K32: =J32-3000000 -> 153551.54 | L32: =J32/3000000 -> 1.0511838 | M32: =G32*8.5% -> 7161.3239
C33: 45921 | D33: =AVERAGE(G13:G33) -> 101627.03 | E33: =D33*30 -> 3048811 | F33: 45921 | G33: =PRODUÇAO!AB37 -> 31800 | H33: =H32+G33 -> 2134167.7 | I33: =H33/3000000 -> 0.71138923 | J33: =H33/21*30 -> 3048811 | K33: =J33-3000000 -> 48810.989 | L33: =J33/3000000 -> 1.0162703 | M33: =G33*8.5% -> 2703
C34: 45922 | D34: =AVERAGE(G13:G34) -> 102839.89 | E34: =D34*30 -> 3085196.6 | F34: 45922 | G34: =PRODUÇAO!AC37 -> 128309.82 | H34: =H33+G34 -> 2262477.5 | I34: =H34/3000000 -> 0.75415917 | J34: =H34/22*30 -> 3085196.6 | K34: =J34-3000000 -> 85196.608 | L34: =J34/3000000 -> 1.0283989 | M34: =G34*8.5% -> 10906.335
C35: 45923 | D35: =AVERAGE(G13:G35) -> 100094.43 | E35: =D35*30 -> 3002832.8 | F35: 45923 | G35: =PRODUÇAO!AD37 -> 39694.31 | H35: =H34+G35 -> 2302171.8 | I35: =H35/3000000 -> 0.76739061 | J35: =H35/23*30 -> 3002832.8 | K35: =J35-3000000 -> 2832.8118 | L35: =J35/3000000 -> 1.0009443 | M35: =G35*8.5% -> 3374.0163
C36: 45924 | D36: =AVERAGE(G13:G36) -> 102306.22 | E36: =D36*30 -> 3069186.5 | F36: 45924 | G36: =PRODUÇAO!AE37 -> 153177.35 | H36: =H35+G36 -> 2455349.2 | I36: =H36/3000000 -> 0.81844972 | J36: =H36/24*30 -> 3069186.5 | K36: =J36-3000000 -> 69186.465 | L36: =J36/3000000 -> 1.0230622 | M36: =G36*8.5% -> 13020.075
C37: 45925 | D37: =AVERAGE(G13:G37) -> 101858.82 | E37: =D37*30 -> 3055764.6 | F37: 45925 | G37: =PRODUÇAO!AF37 -> 91121.36 | H37: =H36+G37 -> 2546470.5 | I37: =H37/3000000 -> 0.84882351 | J37: =H37/25*30 -> 3055764.6 | K37: =J37-3000000 -> 55764.639 | L37: =J37/3000000 -> 1.0185882 | M37: =G37*8.5% -> 7745.3156
C38: 45926 | D38: =AVERAGE(G13:G38) -> 103382.85 | E38: =D38*30 -> 3101485.5 | F38: 45926 | G38: =PRODUÇAO!AG37 -> 141483.6 | H38: =H37+G38 -> 2687954.1 | I38: =H38/3000000 -> 0.89598471 | J38: =H38/26*30 -> 3101485.5 | K38: =J38-3000000 -> 101485.54 | L38: =J38/3000000 -> 1.0338285 | M38: =G38*8.5% -> 12026.106
C39: 45927 | D39: =AVERAGE(G13:G39) -> 101989.76 | E39: =D39*30 -> 3059692.7 | F39: 45927 | G39: =PRODUÇAO!AH37 -> 65769.27 | H39: =H38+G39 -> 2753723.4 | I39: =H39/3000000 -> 0.9179078 | J39: =H39/27*30 -> 3059692.7 | K39: =J39-3000000 -> 59692.669 | L39: =J39/3000000 -> 1.0198976 | M39: =G39*8.5% -> 5590.388
C40: 45928 | D40: =AVERAGE(G13:G40) -> 100604.41 | E40: =D40*30 -> 3018132.2 | F40: 45928 | G40: =PRODUÇAO!AI37 -> 63200 | H40: =H39+G40 -> 2816923.4 | I40: =H40/3000000 -> 0.93897447 | J40: =H40/28*30 -> 3018132.2 | K40: =J40-3000000 -> 18132.217 | L40: =J40/3000000 -> 1.0060441 | M40: =G40*8.5% -> 5372
C41: 45929 | D41: =AVERAGE(G13:G41) -> 100771.7 | E41: =D41*30 -> 3023151.1 | F41: 45929 | G41: =PRODUÇAO!AJ37 -> 105455.95 | H41: =H40+G41 -> 2922379.4 | I41: =H41/3000000 -> 0.97412645 | J41: =H41/29*30 -> 3023151.1 | K41: =J41-3000000 -> 23151.054 | L41: =J41/3000000 -> 1.007717 | M41: =G41*8.5% -> 8963.7558
C42: 45930 | D42: =AVERAGE(G13:G42) -> 105617.51 | E42: =D42*30 -> 3168525.2 | F42: 45930 | G42: =PRODUÇAO!AK37 -> 246145.86 | H42: =H41+G42 -> 3168525.2 | I42: =H42/3000000 -> 1.0561751 | J42: =H42/30*30 -> 3168525.2 | K42: =J42-3000000 -> 168525.21 | L42: =J42/3000000 -> 1.0561751 | M42: =G42*8.5% -> 20922.398
D43: =AVERAGE(D13:D42) -> 100405.79 | K43: =J43-3000000 -> -3000000 | M43: =SUM(M13:M42) -> 269324.64

Sheet PRODUÇAO
A4: Motorista | B4: CPF | C4: Cavalo | D4: 1º Reboque | E4: 2º Reboque | F4: CONTATO | G4: Tipo | H4: 45901 | I4: 45902 | J4: 45903 | K4: 45904 | L4: 45905 | M4: 45906 | N4: 45907 | O4: 45908 | P4: 45909 | Q4: 45910 | R4: 45911 | S4: 45912 | T4: 45913 | U4: 45914 | V4: 45915 | W4: 45916 | X4: 45917 | Y4: 45918 | Z4: 45919 | AA4: 45920 | AB4: 45921 | AC4: 45922 | AD4: 45923 | AE4: 45924 | AF4: 45925 | AG4: 45926 | AH4: 45927 | AI4: 45928 | AJ4: 45929 | AK4: 45930 | AL4: TOTAL | AM4: MEDIA | AN4: COMISSÃO
A5: Ademar Xavier Rocha | B5: 809.679.221-00 | C5: REN-1I09 | D5: ONS - 5741 | E5: ONS - 5781 | F5: (61) 99559-9992 | G5: Rodotrem Graneleiro | I5: 0 | J5: 0 | K5: 0 | L5: 0 | M5: 3761.62 | N5: 0 | O5: 0 | P5: 0 | Q5: 0 | R5: 0 | S5: 0 | T5: 20099.95 | U5: 0 | V5: 0 | W5: 0 | X5: 0 | Y5: 0 | Z5: 36100 | AA5: 0 | AB5: 0 | AC5: 0 | AD5: 0 | AE5: 0 | AF5: 0 | AG5: 0 | AH5: 0 | AI5: 0 | AJ5: 0 | AK5: 32945.4 | AL5: =SUM(H5:AK5) -> 92906.97 | AM5: =AVERAGE(H5:AK5) -> 3203.6886 | AN5: =AL5*8.5% -> 7897.0925
A6: Alison Rodrigues da Silva SA | B6: 038.829.351-97 | C6: RBL-4E27 | D6: GZV-9G76 | E6: EOE-3B10 | F6: (61) 99980-1995 | G6: Rodotrem Graneleiro | H6: 31203.85 | I6: 0 | J6: 0 | K6: 0 | L6: 36100 | M6: 0 | N6: 0 | O6: 0 | P6: 0 | Q6: 0 | R6: 0 | S6: 0 | T6: 0 | U6: 0 | V6: 0 | W6: 0 | Y6: 28020.2 | Z6: 0 | AA6: 0 | AB6: 0 | AC6: 0 | AD6: 0 | AE6: 23900 | AF6: 0 | AG6: 0 | AH6: 0 | AI6: 0 | AJ6: 0 | AK6: 6878.88 | AL6: =SUM(H6:AK6) -> 126102.93 | AM6: =AVERAGE(H6:AK6) -> 4348.3769 | AN6: =AL6*8.5% -> 10718.749
A7: Antonio Leopoldino sobrinho | B7: 529.666.071-49 | C7: SDG-3C21 | D7: PAE-9952 | E7: PAE-9953 | F7: (61) 99648-6312 | G7: Rodotrem Graneleiro | H7: 6694.31 | I7: 0 | J7: 6854.28 | K7: 6694.31 | L7: 0 | M7: 6726.87 | N7: 0 | O7: 0 | P7: 0 | Q7: 6694.31 | R7: 6854.28 | S7: 0 | T7: 6694.31 | U7: 0 | V7: 0 | W7: 6726.87 | X7: 0 | Y7: 0 | Z7: 6694.31 | AA7: 0 | AB7: 0 | AC7: 0 | AD7: 0 | AE7: 44924.52 | AF7: 0 | AG7: 0 | AH7: 0 | AI7: 0 | AJ7: 0 | AK7: 18759.87 | AL7: =SUM(H7:AK7) -> 124318.24 | AM7: =AVERAGE(H7:AK7) -> 4143.9413 | AN7: =AL7*8.5% -> 10567.05
A8: Arthur de Almeida Mascarenhas | B8: 044.559.691-01 | C8: SDA-2H39 | D8: AXH-2C39 | E8: AXH-2C40 | F8: (61) 99447-6996 | G8: Rodotrem Graneleiro | I8: 0 | J8: 0 | K8: 0 | L8: 0 | M8: 12009.03 | N8: 0 | O8: 0 | P8: 0 | Q8: 31548.9 | R8: 0 | S8: 0 | T8: 0 | U8: 0 | V8: 0 | W8: 13503.6 | X8: 0 | Y8: 0 | Z8: 31265.65 | AA8: 0 | AB8: 0 | AC8: 0 | AD8: 0 | AE8: 0 | AF8: 0 | AG8: 12279 | AH8: 0 | AI8: 0 | AJ8: 0 | AK8: 34076.63 | AL8: =SUM(H8:AK8) -> 134682.81 | AM8: =AVERAGE(H8:AK8) -> 4644.2348 | AN8: =AL8*8.5% -> 11448.039
A9: Carlos Sebastião Oliveira da Silva | B9: 074.632.254-29 | C9: TFZ-9E59 | D9: HOF-5G14 | E9: HOF-5G10 | F9: (62) 99665-9462 | G9: Rodotrem Graneleiro | I9: 0 | J9: 0 | K9: 0 | L9: 0 | M9: 0 | N9: 0 | O9: 15000 | P9: 0 | Q9: 0 | R9: 0 | S9: 0 | T9: 32645.55 | U9: 0 | V9: 0 | W9: 0 | X9: 0 | Y9: 0 | Z9: 0 | AA9: 0 | AB9: 0 | AC9: 18759.87 | AD9: 0 | AE9: 0 | AF9: 0 | AG9: 0 | AH9: 0 | AI9: 0 | AJ9: 0 | AK9: 0 | AL9: =SUM(H9:AK9) -> 66405.42 | AM9: =AVERAGE(H9:AK9) -> 2289.8421 | AN9: =AL9*8.5% -> 5644.4607
A10: Cristiano Martins da Silva | B10: 024.251.321-20 | C10: REK-0D67 | D10: PRW-8G54 | E10: PRW-8G64 | F10: (61) 99426-8741 | G10: Rodotrem Graneleiro | I10: 0 | J10: 0 | K10: 0 | L10: 0 | M10: 0 | N10: 0 | O10: 0 | P10: 0 | Q10: 29634 | R10: 0 | S10: 0 | T10: 0 | U10: 0 | V10: 0 | W10: 0 | X10: 0 | Y10: 0 | Z10: 24000 | AA10: 0 | AB10: 0 | AC10: 0 | AD10: 0 | AE10: 0 | AF10: 0 | AG10: 0 | AH10: 0 | AI10: 0 | AJ10: 0 | AK10: 0 | AL10: =SUM(H10:AK10) -> 53634 | AM10: =AVERAGE(H10:AK10) -> 1849.4483 | AN10: =AL10*8.5% -> 4558.89
A11: Edvan Pereira Soares | B11: 863.646.421-87 | C11: RCE-0I83 | D11: MFT-6623 | E11: ONS-7G44 | F11: (62) 99152-8240 | G11: Rodotrem Graneleiro | I11: 24000 | J11: 0 | K11: 0 | L11: 0 | M11: 0 | N11: 0 | O11: 0 | P11: 0 | Q11: 31142.05 | R11: 0 | S11: 0 | T11: 0 | U11: 0 | V11: 0 | W11: 0 | X11: 23900 | Y11: 0 | Z11: 0 | AA11: 0 | AB11: 0 | AC11: 0 | AD11: 0 | AE11: 6059.05 | AF11: 0 | AG11: 0 | AH11: 0 | AI11: 0 | AJ11: 31296.55 | AK11: 0 | AL11: =SUM(H11:AK11) -> 116397.65 | AM11: =AVERAGE(H11:AK11) -> 4013.7121 | AN11: =AL11*8.5% -> 9893.8003
A12: Paulo Machado dos Santos | B12: 291.458.131-91 | C12: RCD-7D72 | D12: OOC-7A05 | E12: OOB-7A05 | F12: (62) 99502-8337 | G12: Rodotrem Graneleiro | H12: 6694.31 | I12: 6694.31 | J12: 6854.28 | K12: 6694.31 | L12: 6726.87 | M12: 0 | N12: 0 | O12: 0 | P12: 6694.31 | Q12: 6854.28 | R12: 6694.31 | S12: 6854.28 | T12: 0 | U12: 0 | V12: 6694.31 | W12: 0 | X12: 0 | Y12: 0 | Z12: 0 | AA12: 6726.87 | AB12: 0 | AC12: 0 | AD12: 6694.31 | AE12: 0 | AF12: 6726.87 | AG12: 0 | AH12: 6694.31 | AI12: 0 | AJ12: 6726.87 | AK12: 0 | AL12: =SUM(H12:AK12) -> 101024.8 | AM12: =AVERAGE(H12:AK12) -> 3367.4933 | AN12: =AL12*8.5% -> 8587.108
A13: Flavio Paiva dos Santos | B13: 036.626.214-95 | C13: RBL-9C93 | D13: PRY-0A53 | E13: PRX-7J53 | F13: (61) 98458-6062 | G13: Rodotrem Graneleiro | I13: 31075.1 | J13: 0 | K13: 0 | L13: 0 | M13: 0 | N13: 0 | O13: 0 | P13: 0 | Q13: 0 | R13: 24600 | S13: 0 | T13: 0 | U13: 0 | V13: 0 | W13: 0 | X13: 22000 | Y13: 0 | Z13: 0 | AA13: 15624 | AB13: 0 | AC13: 0 | AD13: 0 | AE13: 0 | AF13: 0 | AG13: 24000 | AH13: 0 | AI13: 0 | AJ13: 0 | AK13: 0 | AL13: =SUM(H13:AK13) -> 117299.1 | AM13: =AVERAGE(H13:AK13) -> 4044.7966 | AN13: =AL13*8.5% -> 9970.4235
A14: Gilmar Lemes Moreira | B14: 331.607.241-15 | C14: RSA - 6F17 | D14: MKQ-9H98 | E14: MKQ-9D98 | F14: (61) 98322-8230 | G14: Rodotrem Graneleiro | I14: 0 | J14: 0 | K14: 24600 | L14: 0 | M14: 0 | N14: 0 | O14: 0 | P14: 0 | Q14: 0 | R14: 0 | S14: 29088 | T14: 0 | U14: 0 | V14: 0 | W14: 0 | X14: 0 | Z14: 0 | AA14: 24600 | AB14: 0 | AC14: 0 | AD14: 0 | AE14: 0 | AF14: 0 | AG14: 31286.25 | AH14: 0 | AI14: 0 | AJ14: 0 | AK14: 0 | AL14: =SUM(H14:AK14) -> 109574.25 | AM14: =AVERAGE(H14:AK14) -> 3913.3661 | AN14: =AL14*8.5% -> 9313.8113
A15: Gustavo Alves Pereira | B15: 088.328.519-38 | C15: FSI - 2I68 | D15: REK-9E31 | E15: REK-9E32 | F15: (62) 98520-5053 | G15: Rodotrem Graneleiro | I15: 0 | J15: 3300 | K15: 0 | L15: 0 | M15: 0 | N15: 0 | O15: 2310 | P15: 0 | Q15: 4796.17 | R15: 4881.58 | S15: 0 | T15: 0 | U15: 0 | V15: 0 | W15: 4796.17 | X15: 0 | Y15: 4817.88 | Z15: 0 | AA15: 0 | AB15: 0 | AC15: 4796.17 | AD15: 0 | AE15: 4881.58 | AF15: 4796.17 | AG15: 0 | AH15: 4817.88 | AI15: 0 | AJ15: 4796.17 | AK15: 0 | AL15: =SUM(H15:AK15) -> 48989.77 | AM15: =AVERAGE(H15:AK15) -> 1689.3024 | AN15: =AL15*8.5% -> 4164.1304
A16: Irley Alberto Silva Souza | B16: 016.615.751-10 | C16: TFK-5A29 | D16: RBS-5J93 | E16: RBS-6A43 | F16: (61) 99257-7216 | G16: Rodotrem Graneleiro | I16: 6726.87 | J16: 0 | K16: 6694.31 | L16: 6854.28 | M16: 0 | N16: 0 | O16: 6694.31 | P16: 0 | Q16: 6854.28 | R16: 6694.31 | S16: 0 | T16: 6726.87 | U16: 0 | V16: 0 | W16: 0 | X16: 6694.31 | Y16: 0 | Z16: 0 | AA16: 0 | AB16: 0 | AC16: 22000 | AD16: 0 | AE16: 0 | AF16: 0 | AG16: 0 | AH16: 0 | AI16: 16000 | AJ16: 0 | AK16: 0 | AL16: =SUM(H16:AK16) -> 91939.54 | AM16: =AVERAGE(H16:AK16) -> 3170.329 | AN16: =AL16*8.5% -> 7814.8609
A17: Jariel Ferreira Lima | B17: 006.344.131-47 | C17: SDO-1A48 | D17: GAJ-0D53 | E17: GKF-1B94 | F17: (61) 99822-2661 | G17: Rodotrem Sider | I17: 0 | J17: 0 | K17: 0 | L17: 0 | M17: 0 | N17: 0 | O17: 0 | P17: 0 | Q17: 0 | R17: 0 | S17: 0 | T17: 16110 | U17: 0 | V17: 0 | W17: 0 | X17: 0 | Y17: 0 | Z17: 31646.75 | AA17: 0 | AB17: 0 | AC17: 0 | AD17: 0 | AE17: 0 | AF17: 0 | AG17: 0 | AH17: 13165.03 | AI17: 0 | AJ17: 0 | AK17: 37853.05 | AL17: =SUM(H17:AK17) -> 98774.83 | AM17: =AVERAGE(H17:AK17) -> 3406.0286 | AN17: =AL17*8.5% -> 8395.8606
A18: Jose Junho Ferreira | B18: 024.626.833-64 | C18: SDG-3C81 | D18: QTR-6809 | E18: RBK-7E38 | F18: (61) 99994-7737 | G18: Rodotrem Sider | I18: 0 | J18: 0 | K18: 0 | L18: 36100 | M18: 0 | N18: 0 | O18: 0 | P18: 0 | Q18: 0 | R18: 0 | S18: 0 | T18: 0 | U18: 0 | V18: 0 | W18: 0 | X18: 0 | Y18: 28078 | Z18: 0 | AA18: 0 | AB18: 0 | AC18: 0 | AD18: 0 | AE18: 0 | AF18: 26300 | AG18: 0 | AH18: 0 | AI18: 0 | AJ18: 0 | AK18: 43517.52 | AL18: =SUM(H18:AK18) -> 133995.52 | AM18: =AVERAGE(H18:AK18) -> 4620.5352 | AN18: =AL18*8.5% -> 11389.619
A19: Julio Cesar Padilha Simoes | B19: 056.869.581-06 | C19: RCC-7E22 | D19: RBU - 7B44 | E19: RBU - 7D14 | F19: (61) 98185-5916 | G19: Rodotrem Sider | I19: 0 | J19: 5759.89 | K19: 0 | L19: 0 | M19: 0 | N19: 0 | O19: 0 | P19: 19841.98 | Q19: 0 | R19: 0 | S19: 0 | T19: 0 | U19: 0 | V19: 0 | W19: 0 | X19: 24000 | Y19: 0 | Z19: 0 | AA19: 0 | AB19: 0 | AC19: 0 | AD19: 0 | AE19: 31430.45 | AF19: 0 | AG19: 0 | AH19: 0 | AI19: 0 | AJ19: 0 | AK19: 0 | AL19: =SUM(H19:AK19) -> 81032.32 | AM19: =AVERAGE(H19:AK19) -> 2794.2179 | AN19: =AL19*8.5% -> 6887.7472
A20: Kelson Castro Chaves | B20: 857.120.191-91 | C20: RCM-1H95 | D20: FPT-0G91 | E20: GDX-5B62 | F20: (61) 99292-1292 | G20: Rodotrem Sider | H20: 5621.68 | I20: 0 | J20: 31152.35 | K20: 0 | L20: 0 | M20: 0 | N20: 0 | O20: 0 | P20: 0 | Q20: 12744.05 | R20: 0 | S20: 0 | T20: 32960 | U20: 0 | V20: 0 | W20: 0 | X20: 0 | Y20: 32655.09 | Z20: 0 | AA20: 0 | AB20: 0 | AC20: 6726.87 | AD20: 0 | AE20: 6694.31 | AF20: 0 | AG20: 44921.52 | AH20: 0 | AI20: 0 | AJ20: 0 | AK20: 0 | AL20: =SUM(H20:AK20) -> 173475.87 | AM20: =AVERAGE(H20:AK20) -> 5782.529 | AN20: =AL20*8.5% -> 14745.449
A21: Lucas Carvalho Pereira | B21: 020.530.081-21 | C21: TFP-2E23 | D21: GDI-4D01 | E21: FMP-9E71 | F21: (61) 99869-6347 | G21: Rodotrem Sider | I21: 0 | J21: 0 | K21: 0 | L21: 0 | M21: 0 | N21: 0 | O21: 15000 | P21: 0 | Q21: 0 | R21: 0 | S21: 0 | T21: 0 | U21: 0 | V21: 0 | W21: 0 | X21: 16000 | Y21: 0 | Z21: 0 | AA21: 0 | AB21: 0 | AC21: 16000 | AD21: 0 | AE21: 12000 | AF21: 0 | AG21: 0 | AH21: 0 | AI21: 0 | AJ21: 20000 | AK21: 0 | AL21: =SUM(H21:AK21) -> 79000 | AM21: =AVERAGE(H21:AK21) -> 2724.1379 | AN21: =AL21*8.5% -> 6715
A22: Luciano Quintanilha Gomes | B22: 078.590.297-07 | C22: TFQ-0J19 | D22: RBM - 3G03 | E22: RBM - 3F93 | F22: (62) 98157-6973 | G22: Rodotrem Sider | I22: 0 | J22: 0 | K22: 0 | L22: 0 | M22: 0 | N22: 0 | O22: 0 | P22: 0 | Q22: 0 | R22: 0 | S22: 0 | T22: 14592 | U22: 0 | V22: 0 | W22: 0 | X22: 0 | Y22: 0 | Z22: 0 | AA22: 0 | AB22: 16000 | AC22: 0 | AD22: 0 | AE22: 0 | AF22: 0 | AG22: 16000 | AH22: 0 | AI22: 0 | AJ22: 16000 | AK22: 0 | AL22: =SUM(H22:AK22) -> 62592 | AM22: =AVERAGE(H22:AK22) -> 2158.3448 | AN22: =AL22*8.5% -> 5320.32
A23: Luiz Claudio Pessoa | B23: 442.761.411-68 | C23: PRP-7B62 | D23: RBN-3H25 | E23: RBN-3H75 | F23: (61) 99696-0881 | G23: Rodotrem Sider | I23: 0 | J23: 0 | K23: 0 | M23: 23937.56 | N23: 0 | O23: 0 | P23: 0 | Q23: 0 | R23: 0 | S23: 0 | T23: 36100 | U23: 0 | V23: 0 | W23: 0 | X23: 0 | Y23: 0 | Z23: 0 | AA23: 0 | AB23: 0 | AC23: 0 | AD23: 0 | AE23: 0 | AF23: 21842.2 | AG23: 0 | AH23: 0 | AI23: 0 | AJ23: 0 | AK23: 0 | AL23: =SUM(H23:AK23) -> 81879.76 | AM23: =AVERAGE(H23:AK23) -> 2924.2771 | AN23: =AL23*8.5% -> 6959.7796
A24: Luiz Ricardo Melo de Almeida | B24: 040.411.491-18 | C24: SDG-1G91 | D24: RBW-0G43 | E24: RBV-7H23 | F24: (61) 99191-6324 | G24: Rodotrem Sider | H24: 5199.33 | I24: 0 | J24: 6694.31 | K24: 6854.28 | L24: 6694.31 | M24: 0 | N24: 0 | O24: 6854.28 | P24: 32960 | Q24: 0 | R24: 0 | S24: 0 | T24: 0 | U24: 0 | V24: 0 | W24: 0 | X24: 0 | Y24: 15210 | Z24: 0 | AA24: 0 | AB24: 0 | AC24: 0 | AD24: 33000 | AE24: 0 | AF24: 0 | AG24: 0 | AH24: 0 | AI24: 0 | AJ24: 0 | AK24: 0 | AL24: =SUM(H24:AK24) -> 113466.51 | AM24: =AVERAGE(H24:AK24) -> 3782.217 | AN24: =AL24*8.5% -> 9644.6534
A25: Marcelo Silva Sousa | B25: 783.744.211-34 | C25: REO-5A75 | D25: QTO-1298 | E25: QTO-1088 | F25: (61) 99317-3916 | G25: Rodotrem Sider | I25: 0 | J25: 0 | K25: 0 | L25: 28404.11 | M25: 0 | N25: 0 | O25: 0 | P25: 0 | Q25: 0 | R25: 0 | S25: 0 | T25: 13659.5 | U25: 0 | V25: 0 | W25: 0 | X25: 0 | Y25: 0 | Z25: 0 | AA25: 0 | AB25: 15000 | AC25: 0 | AD25: 0 | AE25: 0 | AF25: 0 | AG25: 0 | AH25: 21092.05 | AI25: 0 | AJ25: 0 | AK25: 0 | AL25: =SUM(H25:AK25) -> 78155.66 | AM25: =AVERAGE(H25:AK25) -> 2695.0228 | AN25: =AL25*8.5% -> 6643.2311
A26: Fabrício Bernadino de Brito | B26: 079.915.486-51 | C26: SDH-1G58 | D26: SDJ-7C68 | E26: SCJ-1J98 | F26: (61) 99908-5809 | G26: Rodotrem Sider | I26: 13391.21 | J26: 0 | K26: 0 | L26: 16000 | M26: 0 | N26: 0 | O26: 16000 | P26: 0 | Q26: 0 | R26: 0 | S26: 0 | T26: 16000 | U26: 0 | V26: 0 | W26: 12000 | X26: 0 | Y26: 0 | Z26: 0 | AA26: 20000 | AB26: 0 | AC26: 0 | AD26: 0 | AE26: 0 | AF26: 12000 | AG26: 0 | AH26: 20000 | AI26: 0 | AJ26: 0 | AK26: 0 | AL26: =SUM(H26:AK26) -> 125391.21 | AM26: =AVERAGE(H26:AK26) -> 4323.8348 | AN26: =AL26*8.5% -> 10658.253
A27: Marcos Antonio Martins | B27: 599.872.431-34 | C27: SDL-5J68 | D27: RBR-2G14 | E27: RBR-2G44 | F27: (61) 99867-1574 | G27: Rodotrem Sider | H27: 6726.87 | I27: 0 | J27: 6694.31 | K27: 0 | L27: 6854.28 | M27: 0 | N27: 0 | O27: 6694.31 | P27: 6854.28 | Q27: 6694.31 | R27: 0 | S27: 14540.79 | T27: 0 | U27: 0 | V27: 0 | W27: 0 | X27: 0 | Y27: 6694.31 | Z27: 0 | AA27: 0 | AB27: 0 | AC27: 22000 | AD27: 0 | AE27: 0 | AF27: 0 | AG27: 0 | AH27: 0 | AI27: 0 | AJ27: 26636.36 | AK27: 0 | AL27: =SUM(H27:AK27) -> 110389.82 | AM27: =AVERAGE(H27:AK27) -> 3679.6607 | AN27: =AL27*8.5% -> 9383.1347
A28: Mauro Batista de Lima | B28: 413.502.865-91 | C28: RBX-5F42 | D28: FJH-7E96 | E28: GFR-0J56 | F28: (61) 99310-4960 | G28: Rodotrem Sider | I28: 0 | J28: 0 | K28: 0 | L28: 0 | M28: 0 | N28: 0 | O28: 0 | P28: 0 | Q28: 23900 | R28: 0 | S28: 0 | T28: 0 | U28: 0 | V28: 0 | W28: 0 | X28: 0 | Y28: 0 | Z28: 0 | AA28: 0 | AB28: 0 | AC28: 31332.6 | AD28: 0 | AE28: 0 | AF28: 0 | AG28: 0 | AH28: 0 | AI28: 23200 | AJ28: 0 | AK28: 0 | AL28: =SUM(H28:AK28) -> 78432.6 | AM28: =AVERAGE(H28:AK28) -> 2704.5724 | AN28: =AL28*8.5% -> 6666.771
A29: Murilo Costa Silva | B29: 003.132.941-19 | C29: RVS-9J69 | D29: TFA-8C71 | E29: TFQ-8F21 | F29: (61) 98206-4412 | G29: Rodotrem Sider | I29: 18000 | J29: 0 | K29: 0 | L29: 44761.68 | M29: 0 | N29: 0 | O29: 0 | P29: 18000 | Q29: 0 | R29: 0 | S29: 44946 | T29: 0 | U29: 0 | V29: 0 | W29: 18000 | X29: 0 | Y29: 0 | Z29: 44761.68 | AA29: 0 | AB29: 0 | AC29: 0 | AD29: 0 | AE29: 0 | AF29: 0 | AG29: 12996.83 | AH29: 0 | AI29: 0 | AJ29: 0 | AK29: 32960 | AL29: =SUM(H29:AK29) -> 234426.19 | AM29: =AVERAGE(H29:AK29) -> 8083.6617 | AN29: =AL29*8.5% -> 19926.226
A30: Ralisson Duarte de Souza | B30: 896.342.411-15 | C30: QUJ-5G26 | D30: GJR-6I44 | E30: GHL-8I33 | F30: (61) 99946-8725 | G30: Rodotrem Sider | I30: 0 | J30: 17300 | K30: 0 | L30: 0 | M30: 0 | N30: 0 | O30: 0 | P30: 0 | Q30: 0 | R30: 0 | S30: 15552.94 | T30: 0 | U30: 0 | V30: 0 | W30: 0 | X30: 0 | Y30: 0 | Z30: 0 | AA30: 17300 | AB30: 0 | AC30: 0 | AD30: 0 | AE30: 0 | AF30: 0 | AG30: 0 | AH30: 0 | AI30: 0 | AJ30: 0 | AK30: 21280.2 | AL30: =SUM(H30:AK30) -> 71433.14 | AM30: =AVERAGE(H30:AK30) -> 2463.2117 | AN30: =AL30*8.5% -> 6071.8169
A31: Railandher Nunes dos Santos | B31: 064.769-571-55 | C31: RVQ-1J85 | D31: SCT-8F58 | E31: SDH-8D38 | F31: (61) 99562-5503 | G31: Rodotrem Sider | I31: 0 | J31: 0 | K31: 32626.79 | M31: 0 | N31: 0 | O31: 0 | P31: 0 | Q31: 0 | R31: 0 | S31: 25600 | T31: 0 | U31: 0 | V31: 0 | W31: 0 | X31: 0 | Y31: 0 | Z31: 27000 | AA31: 0 | AB31: 0 | AC31: 0 | AD31: 0 | AE31: 0 | AF31: 0 | AG31: 0 | AH31: 0 | AI31: 24000 | AJ31: 0 | AK31: 0 | AL31: =SUM(H31:AK31) -> 109226.79 | AM31: =AVERAGE(H31:AK31) -> 3900.9568 | AN31: =AL31*8.5% -> 9284.2772
A32: Renato de Jesus Souza | B32: 021.156.911-99 | C32: SDH-7A25 | D32: RBP - 5A93 | E32: XXXXXX | F32: (61) 99107-6723 | G32: LS Sider | H32: 6726.87 | I32: 6694.31 | K32: 0 | L32: 6854.28 | M32: 0 | N32: 0 | O32: 0 | P32: 6694.31 | Q32: 0 | R32: 6854.28 | S32: 0 | T32: 0 | U32: 0 | V32: 6694.31 | W32: 6726.37 | X32: 0 | Y32: 0 | Z32: 0 | AA32: 0 | AB32: 0 | AC32: 6694.31 | AD32: 0 | AE32: 0 | AF32: 6726.87 | AG32: 0 | AH32: 0 | AI32: 0 | AJ32: 0 | AK32: 0 | AL32: =SUM(H32:AK32) -> 60665.91 | AM32: =AVERAGE(H32:AK32) -> 2091.9279 | AN32: =AL32*8.5% -> 5156.6024
A33: Ronaldo Duarte | B33: 954.452.421-53 | C33: JBE-1E97 | D33: GHB-7F27 | E33: XXXXXX | F33: (61) 98416-2357 | G33: LS Sider | J33: 0 | K33: 0 | L33: 0 | M33: 0 | N33: 0 | O33: 0 | P33: 0 | Q33: 12996.83 | R33: 0 | S33: 0 | T33: 0 | U33: 23680 | V33: 0 | W33: 0 | X33: 0 | Y33: 0 | Z33: 10729.54 | AA33: 0 | AB33: 800 | AC33: 0 | AD33: 0 | AE33: 21852.76 | AF33: 0 | AG33: 0 | AH33: 0 | AI33: 0 | AJ33: 0 | AK33: 11180 | AL33: =SUM(H33:AK33) -> 81239.13 | AM33: =AVERAGE(H33:AK33) -> 2901.3975 | AN33: =AL33*8.5% -> 6905.3261
A34: Valmir de Souza Santos | B34: 649.462.151-15 | C34: TFY-6F22 | D34: DJV-1A46 | E34: XXXXXX | F34: (61) 99994-1121 | G34: LS Sider | I34: 44761.68 | J34: 0 | K34: 0 | L34: 0 | M34: 18000 | N34: 0 | O34: 0 | P34: 0 | Q34: 44761.68 | R34: 0 | S34: 0 | T34: 0 | U34: 0 | V34: 18000 | W34: 0 | X34: 0 | Y34: 0 | Z34: 44495.28 | AA34: 0 | AB34: 0 | AC34: 0 | AD34: 0 | AE34: 0 | AF34: 12729.25 | AG34: 0 | AH34: 0 | AI34: 0 | AJ34: 0 | AK34: 6694.31 | AL34: =SUM(H34:AK34) -> 189442.2 | AM34: =AVERAGE(H34:AK34) -> 6532.4897 | AN34: =AL34*8.5% -> 16102.587
A35: Wellington Gomes de Morais | B35: 866.206.221-00 | C35: RCD-5C48 | D35: RCA-5G48 | E35: XXXXXX | F35: (61) 98186-8698 | G35: Graneleiro | I35: 0 | J35: 0 | K35: 0 | L35: 0 | M35: 0 | N35: 0 | O35: 0 | P35: 0 | Q35: 0 | R35: 0 | S35: 0 | T35: 0 | U35: 0 | V35: 0 | W35: 0 | X35: 0 | Y35: 16441.6 | Z35: 0 | AA35: 0 | AB35: 0 | AC35: 0 | AD35: 0 | AE35: 0 | AF35: 0 | AG35: 0 | AH35: 0 | AI35: 0 | AJ35: 0 | AK35: 0 | AL35: =SUM(H35:AK35) -> 16441.6 | AM35: =AVERAGE(H35:AK35) -> 566.95172 | AN35: =AL35*8.5% -> 1397.536
A36: Hometeck | L36: 2113.2324 | Y36: 2240.76 | AE36: 1434.68
C37: DIA | H37: =SUM(H5:H35) -> 68867.22 | I37: =SUM(I5:I35) -> 151343.48 | J37: =SUM(J5:J35) -> 84609.42 | K37: =SUM(K5:K35) -> 84164 | L37: =SUM(L5:L36) -> 197463.04 | M37: =SUM(M5:M36) -> 64435.08 | N37: =SUM(N5:N36) -> 0 | O37: =SUM(O5:O36) -> 68552.9 | P37: =SUM(P5:P36) -> 91044.88 | Q37: =SUM(Q5:Q36) -> 218620.86 | R37: =SUM(R5:R36) -> 56578.76 | S37: =SUM(S5:S36) -> 136582.01 | T37: =SUM(T5:T36) -> 195588.18 | U37: =SUM(U5:U35) -> 23680 | V37: =SUM(V5:V35) -> 31388.62 | W37: =SUM(W5:W35) -> 61753.01 | X37: =SUM(X5:X35) -> 92594.31 | Y37: =SUM(Y5:Y36) -> 134157.84 | Z37: =SUM(Z5:Z35) -> 256693.21 | AA37: =SUM(AA5:AA35) -> 84250.87 | AB37: =SUM(AB5:AB35) -> 31800 | AC37: =SUM(AC5:AC35) -> 128309.82 | AD37: =SUM(AD5:AD35) -> 39694.31 | AE37: =SUM(AE5:AE36) -> 153177.35 | AF37: =SUM(AF5:AF35) -> 91121.36 | AG37: =SUM(AG5:AG35) -> 141483.6 | AH37: =SUM(AH5:AH35) -> 65769.27 | AI37: =SUM(AI5:AI35) -> 63200 | AJ37: =SUM(AJ5:AJ35) -> 105455.95 | AK37: =SUM(AK5:AK35) -> 246145.86 | AL37: =SUM(AL5:AL35) -> 3162736.5 | AM37: =SUM(AM5:AM35) -> 108814.51 | AN37: =SUM(AN5:AN35) -> 268832.61
H38: 45901 | I38: 45902 | J38: 45903 | K38: 45904 | L38: 45905 | M38: 45906 | N38: 45907 | O38: 45908 | P38: 45909 | Q38: 45910 | R38: 45911 | S38: 45912 | T38: 45913 | U38: 45914 | V38: 45915 | W38: 45916 | X38: 45917 | Y38: 45918 | Z38: 45919 | AA38: 45920 | AB38: 45921 | AC38: 45922 | AD38: 45923 | AE38: 45924 | AF38: 45925 | AG38: 45926 | AH38: 45927 | AI38: 45928 | AJ38: 45929 | AK38: 45930

Sheet OUTUBRO
C4: GESTÃO A VISTA DO RESULTADO DURANTE O MÊS VIGENTE
C6: QTD | D6: VEICULO | E6: META MÊS | G6: PRODUÇÃO
C7: 4 | D7: LS | E7: 70000 | G7: =E7*C7 -> 280000
C8: 27 | D8: RODOTREM | E8: 100000 | G8: =E8*C8 -> 2700000
E9: TOTAL | G9: =SUM(G7:G8) -> 2980000
G11: DIGITAR
C12: DIA | D12: MEDIA DIA | E12: ACUMULADO POR MEDIA | F12: DIA | G12: Faturado dia | H12: acumulado mês | I12: META 3.000.000 | J12: PROJEÇAO | K12: DIFERENÇA DA META | L12: COMPARATIVO COM META | M12: COMISSÃO
C13: 45931 | D13: =AVERAGE(G13) -> 89766.45 | E13: =D13*30 -> 2692993.5 | F13: 45931 | G13: ='PRODUÇAO (OUT)'!H42 -> 89766.45 | H13: =G13 -> 89766.45 | I13: =H13/3000000 -> 0.02992215 | J13: =H13*30 -> 2692993.5 | K13: =J13-3000000 -> -307006.5 | L13: =J13/3000000 -> 0.8976645 | M13: =G13*8.6% -> 7719.9147
C14: 45932 | D14: =AVERAGE(G13:G14) -> 71899.255 | E14: =D14*30 -> 2156977.7 | F14: 45932 | G14: ='PRODUÇAO (OUT)'!I42 -> 54032.06 | H14: =H13+G14 -> 143798.51 | I14: =H14/3000000 -> 0.047932837 | J14: =H14/2*30 -> 2156977.7 | K14: =J14-3000000 -> -843022.35 | L14: =J14/3000000 -> 0.71899255 | M14: =G14*8.6% -> 4646.7572
C15: 45933 | D15: =AVERAGE(G13:G15) -> 71528.887 | E15: =D15*30 -> 2145866.6 | F15: 45933 | G15: ='PRODUÇAO (OUT)'!J42 -> 70788.15 | H15: =H14+G15 -> 214586.66 | I15: =H15/3000000 -> 0.071528887 | J15: =H15/3*30 -> 2145866.6 | K15: =J15-3000000 -> -854133.4 | L15: =J15/3000000 -> 0.71528887 | M15: =G15*8.6% -> 6087.7809
C16: 45934 | D16: =AVERAGE(G13:G16) -> 69328.385 | E16: =D16*30 -> 2079851.6 | F16: 45934 | G16: ='PRODUÇAO (OUT)'!K42 -> 62726.88 | H16: =H15+G16 -> 277313.54 | I16: =H16/3000000 -> 0.092437847 | J16: =H16/4*30 -> 2079851.6 | K16: =J16-3000000 -> -920148.45 | L16: =J16/3000000 -> 0.69328385 | M16: =G16*8.6% -> 5394.5117
C17: 45935 | D17: =AVERAGE(G13:G17) -> 55462.708 | E17: =D17*30 -> 1663881.2 | F17: 45935 | G17: ='PRODUÇAO (OUT)'!L42 -> 0 | H17: =H16+G17 -> 277313.54 | I17: =H17/3000000 -> 0.092437847 | J17: =H17/5*30 -> 1663881.2 | K17: =J17-3000000 -> -1336118.8 | L17: =J17/3000000 -> 0.55462708 | M17: =G17*8.6% -> 0
C18: 45936 | D18: =AVERAGE(G13:G18) -> 55773.158 | E18: =D18*30 -> 1673194.8 | F18: 45936 | G18: ='PRODUÇAO (OUT)'!M42 -> 57325.41 | H18: =H17+G18 -> 334638.95 | I18: =H18/3000000 -> 0.11154632 | J18: =H18/6*30 -> 1673194.8 | K18: =J18-3000000 -> -1326805.2 | L18: =J18/3000000 -> 0.55773158 | M18: =G18*8.6% -> 4929.9853
C19: 45937 | D19: =AVERAGE(G13:G19) -> 58390.633 | E19: =D19*30 -> 1751719 | F19: 45937 | G19: ='PRODUÇAO (OUT)'!N42 -> 74095.48 | H19: =H18+G19 -> 408734.43 | I19: =H19/3000000 -> 0.13624481 | J19: =H19/7*30 -> 1751719 | K19: =J19-3000000 -> -1248281 | L19: =J19/3000000 -> 0.58390633 | M19: =G19*8.6% -> 6372.2113
C20: 45938 | D20: =AVERAGE(G13:G20) -> 58882.076 | E20: =D20*30 -> 1766462.3 | F20: 45938 | G20: ='PRODUÇAO (OUT)'!O42 -> 62322.18 | H20: =H19+G20 -> 471056.61 | I20: =H20/3000000 -> 0.15701887 | J20: =H20/8*30 -> 1766462.3 | K20: =J20-3000000 -> -1233537.7 | L20: =J20/3000000 -> 0.58882076 | M20: =G20*8.6% -> 5359.7075
C21: 45939 | D21: =AVERAGE(G13:G21) -> 56924.727 | E21: =D21*30 -> 1707741.8 | F21: 45939 | G21: ='PRODUÇAO (OUT)'!P42 -> 41265.93 | H21: =H20+G21 -> 512322.54 | I21: =H21/3000000 -> 0.17077418 | J21: =H21/9*30 -> 1707741.8 | K21: =J21-3000000 -> -1292258.2 | L21: =J21/3000000 -> 0.56924727 | M21: =G21*8.6% -> 3548.87
C22: 45940 | D22: =AVERAGE(G13:G22) -> 71447.392 | E22: =D22*30 -> 2143421.8 | F22: 45940 | G22: ='PRODUÇAO (OUT)'!Q42 -> 202151.38 | H22: =H21+G22 -> 714473.92 | I22: =H22/3000000 -> 0.23815797 | J22: =H22/10*30 -> 2143421.8 | K22: =J22-3000000 -> -856578.24 | L22: =J22/3000000 -> 0.71447392 | M22: =G22*8.6% -> 17385.019
C23: 45941 | D23: =AVERAGE(G13:G23) -> 70899.253 | E23: =D23*30 -> 2126977.6 | F23: 45941 | G23: ='PRODUÇAO (OUT)'!R42 -> 65417.86 | H23: =H22+G23 -> 779891.78 | I23: =H23/3000000 -> 0.25996393 | J23: =H23/11*30 -> 2126977.6 | K23: =J23-3000000 -> -873022.42 | L23: =J23/3000000 -> 0.70899253 | M23: =G23*8.6% -> 5625.936
C24: 45942 | D24: =AVERAGE(G13:G24) -> 64990.982 | E24: =D24*30 -> 1949729.4 | F24: 45942 | G24: ='PRODUÇAO (OUT)'!S42 -> 0 | H24: =H23+G24 -> 779891.78 | I24: =H24/3000000 -> 0.25996393 | J24: =H24/12*30 -> 1949729.4 | K24: =J24-3000000 -> -1050270.6 | L24: =J24/3000000 -> 0.64990982 | M24: =G24*8.6% -> 0
C25: 45943 | D25: =AVERAGE(G13:G25) -> 69049.065 | E25: =D25*30 -> 2071471.9 | F25: 45943 | G25: ='PRODUÇAO (OUT)'!T42 -> 117746.06 | H25: =H24+G25 -> 897637.84 | I25: =H25/3000000 -> 0.29921261 | J25: =H25/13*30 -> 2071471.9 | K25: =J25-3000000 -> -928528.06 | L25: =J25/3000000 -> 0.69049065 | M25: =G25*8.6% -> 10126.161
C26: 45944 | D26: =AVERAGE(G13:G26) -> 72563.824 | E26: =D26*30 -> 2176914.7 | F26: 45944 | G26: ='PRODUÇAO (OUT)'!U42 -> 118255.69 | H26: =H25+G26 -> 1015893.5 | I26: =H26/3000000 -> 0.33863118 | J26: =H26/14*30 -> 2176914.7 | K26: =J26-3000000 -> -823085.29 | L26: =J26/3000000 -> 0.72563824 | M26: =G26*8.6% -> 10169.989
C27: 45945 | D27: =AVERAGE(G13:G27) -> 71674.886 | E27: =D27*30 -> 2150246.6 | F27: 45945 | G27: ='PRODUÇAO (OUT)'!V42 -> 59229.76 | H27: =H26+G27 -> 1075123.3 | I27: =H27/3000000 -> 0.35837443 | J27: =H27/15*30 -> 2150246.6 | K27: =J27-3000000 -> -849753.42 | L27: =J27/3000000 -> 0.71674886 | M27: =G27*8.6% -> 5093.7594
C28: 45946 | D28: =AVERAGE(G13:G28) -> 71125.575 | E28: =D28*30 -> 2133767.2 | F28: 45946 | G28: ='PRODUÇAO (OUT)'!W42 -> 62885.91 | H28: =H27+G28 -> 1138009.2 | I28: =H28/3000000 -> 0.3793364 | J28: =H28/16*30 -> 2133767.2 | K28: =J28-3000000 -> -866232.75 | L28: =J28/3000000 -> 0.71125575 | M28: =G28*8.6% -> 5408.1883
C29: 45947 | D29: =AVERAGE(G13:G29) -> 75422.926 | E29: =D29*30 -> 2262687.8 | F29: 45947 | G29: ='PRODUÇAO (OUT)'!X42 -> 144180.55 | H29: =H28+G29 -> 1282189.7 | I29: =H29/3000000 -> 0.42739658 | J29: =H29/17*30 -> 2262687.8 | K29: =J29-3000000 -> -737312.21 | L29: =J29/3000000 -> 0.75422926 | M29: =G29*8.6% -> 12399.527
C30: 45948 | D30: =AVERAGE(G13:G30) -> 74188.746 | E30: =D30*30 -> 2225662.4 | F30: 45948 | G30: ='PRODUÇAO (OUT)'!Y42 -> 53207.68 | H30: =H29+G30 -> 1335397.4 | I30: =H30/3000000 -> 0.44513248 | J30: =H30/18*30 -> 2225662.4 | K30: =J30-3000000 -> -774337.62 | L30: =J30/3000000 -> 0.74188746 | M30: =G30*8.6% -> 4575.8605
C31: 45949 | D31: =AVERAGE(G13:G31) -> 70284.075 | E31: =D31*30 -> 2108522.3 | F31: 45949 | G31: ='PRODUÇAO (OUT)'!Z42 -> 0 | H31: =H30+G31 -> 1335397.4 | I31: =H31/3000000 -> 0.44513248 | J31: =H31/19*30 -> 2108522.3 | K31: =J31-3000000 -> -891477.74 | L31: =J31/3000000 -> 0.70284075 | M31: =G31*8.6% -> 0
C32: 45950 | D32: =AVERAGE(G13:G32) -> 70062.358 | E32: =D32*30 -> 2101870.7 | F32: 45950 | G32: ='PRODUÇAO (OUT)'!AA42 -> 65849.73 | H32: =H31+G32 -> 1401247.2 | I32: =H32/3000000 -> 0.46708239 | J32: =H32/20*30 -> 2101870.7 | K32: =J32-3000000 -> -898129.26 | L32: =J32/3000000 -> 0.70062358 | M32: =G32*8.6% -> 5663.0768
C33: 45951 | D33: =AVERAGE(G13:G33) -> 71540.574 | E33: =D33*30 -> 2146217.2 | F33: 45951 | G33: ='PRODUÇAO (OUT)'!AB42 -> 101104.9 | H33: =H32+G33 -> 1502352.1 | I33: =H33/3000000 -> 0.50078402 | J33: =H33/21*30 -> 2146217.2 | K33: =J33-3000000 -> -853782.77 | L33: =J33/3000000 -> 0.71540574 | M33: =G33*8.6% -> 8695.0214
C34: 45952 | D34: =AVERAGE(G13:G34) -> 73322.386 | E34: =D34*30 -> 2199671.6 | F34: 45952 | G34: ='PRODUÇAO (OUT)'!AC42 -> 110740.44 | H34: =H33+G34 -> 1613092.5 | I34: =H34/3000000 -> 0.5376975 | J34: =H34/22*30 -> 2199671.6 | K34: =J34-3000000 -> -800328.41 | L34: =J34/3000000 -> 0.73322386 | M34: =G34*8.6% -> 9523.6778
C35: 45953 | D35: =AVERAGE(G13:G35) -> 77407.96 | E35: =D35*30 -> 2322238.8 | F35: 45953 | G35: ='PRODUÇAO (OUT)'!AD42 -> 167290.59 | H35: =H34+G35 -> 1780383.1 | I35: =H35/3000000 -> 0.59346103 | J35: =H35/23*30 -> 2322238.8 | K35: =J35-3000000 -> -677761.19 | L35: =J35/3000000 -> 0.7740796 | M35: =G35*8.6% -> 14386.991
C36: 45954 | D36: =AVERAGE(G13:G36) -> 79984.775 | E36: =D36*30 -> 2399543.3 | F36: 45954 | G36: ='PRODUÇAO (OUT)'!AE42 -> 139251.52 | H36: =H35+G36 -> 1919634.6 | I36: =H36/3000000 -> 0.6398782 | J36: =H36/24*30 -> 2399543.3 | K36: =J36-3000000 -> -600456.74 | L36: =J36/3000000 -> 0.79984775 | M36: =G36*8.6% -> 11975.631
C37: 45955 | D37: =AVERAGE(G13:G37) -> 78013.198 | E37: =D37*30 -> 2340395.9 | F37: 45955 | G37: ='PRODUÇAO (OUT)'!AF42 -> 30695.34 | H37: =H36+G37 -> 1950329.9 | I37: =H37/3000000 -> 0.65010998 | J37: =H37/25*30 -> 2340395.9 | K37: =J37-3000000 -> -659604.06 | L37: =J37/3000000 -> 0.78013198 | M37: =G37*8.6% -> 2639.7992
C38: 45956 | D38: =AVERAGE(G13:G38) -> 76326.31 | E38: =D38*30 -> 2289789.3 | F38: 45956 | G38: ='PRODUÇAO (OUT)'!AG42 -> 34154.11 | H38: =H37+G38 -> 1984484.1 | I38: =H38/3000000 -> 0.66149469 | J38: =H38/26*30 -> 2289789.3 | K38: =J38-3000000 -> -710210.7 | L38: =J38/3000000 -> 0.7632631 | M38: =G38*8.6% -> 2937.2535
C39: 45957 | D39: =AVERAGE(G13:G39) -> 75542.879 | E39: =D39*30 -> 2266286.4 | F39: 45957 | G39: ='PRODUÇAO (OUT)'!AH42 -> 55173.67 | H39: =H38+G39 -> 2039657.7 | I39: =H39/3000000 -> 0.67988591 | J39: =H39/27*30 -> 2266286.4 | K39: =J39-3000000 -> -733713.63 | L39: =J39/3000000 -> 0.75542879 | M39: =G39*8.6% -> 4744.9356
C40: 45958 | D40: =AVERAGE(G13:G40) -> 75788.103 | E40: =D40*30 -> 2273643.1 | F40: 45958 | G40: ='PRODUÇAO (OUT)'!AI42 -> 82409.15 | H40: =H39+G40 -> 2122066.9 | I40: =H40/3000000 -> 0.70735563 | J40: =H40/28*30 -> 2273643.1 | K40: =J40-3000000 -> -726356.91 | L40: =J40/3000000 -> 0.75788103 | M40: =G40*8.6% -> 7087.1869
C41: 45959 | D41: =AVERAGE(G13:G41) -> 75066.716 | E41: =D41*30 -> 2252001.5 | F41: 45959 | G41: ='PRODUÇAO (OUT)'!AJ42 -> 54867.88 | H41: =H40+G41 -> 2176934.8 | I41: =H41/3000000 -> 0.72564492 | J41: =H41/29*30 -> 2252001.5 | K41: =J41-3000000 -> -747998.52 | L41: =J41/3000000 -> 0.75066716 | M41: =G41*8.6% -> 4718.6377
C42: 45960 | D42: =AVERAGE(G13:G42) -> 74845.518 | E42: =D42*30 -> 2245365.5 | F42: 45960 | G42: ='PRODUÇAO (OUT)'!AK42 -> 68430.77 | H42: =H41+G42 -> 2245365.5 | I42: =H42/3000000 -> 0.74845518 | J42: =H42/31*31 -> 2245365.5 | K42: =J42-3000000 -> -754634.47 | L42: =J42/3000000 -> 0.74845518 | M42: =G42*8.6% -> 5885.0462
C43: 45961 | D43: =AVERAGE(D13:D42) -> 70916.793 | E43: =D43*31 -> 2198420.6 | F43: 45961 | G43: ='PRODUÇAO (OUT)'!AL42 -> 230981.27 | H43: =H42+G43 -> 2476346.8 | I43: =H43/3000000 -> 0.82544893 | J43: =H43/30*30 -> 2476346.8 | K43: =J43-3000000 -> -523653.2 | L43: =J43/3000000 -> 0.82544893 | M43: =G43*8.6% -> 19864.389

Sheet PRODUÇAO (OUT)
A4: Motorista | B4: CPF | C4: Cavalo | D4: 1º Reboque | E4: 2º Reboque | F4: CONTATO | G4: Tipo | H4: 45931 | I4: 45932 | J4: 45933 | K4: 45934 | L4: 45935 | M4: 45936 | N4: 45937 | O4: 45938 | P4: 45939 | Q4: 45940 | R4: 45941 | S4: 45942 | T4: 45943 | U4: 45944 | V4: 45945 | W4: 45946 | X4: 45947 | Y4: 45948 | Z4: 45949 | AA4: 45950 | AB4: 45951 | AC4: 45952 | AD4: 45953 | AE4: 45954 | AF4: 45955 | AG4: 45956 | AH4: 45957 | AI4: 45958 | AJ4: 45959 | AK4: 45960 | AL4: 45961 | AM4: TOTAL | AN4: MEDIA | AO4: COMISSÃO
A5: Ademar Xavier Rocha | B5: 809.679.221-00 | C5: SDH-7A25 | D5: ONS - 5741 | E5: ONS - 5781 | F5: (61) 99559-9992 | G5: Rodotrem Graneleiro | H5: 0 | I5: 0 | J5: 0 | K5: 0 | L5: 0 | M5: 0 | N5: 0 | O5: 0 | P5: 0 | Q5: 0 | R5: 0 | S5: 0 | T5: 0 | U5: 36100 | V5: 0 | W5: 0 | X5: 0 | Y5: 0 | Z5: 0 | AA5: 0 | AB5: 0 | AC5: 0 | AD5: 0 | AE5: 16000 | AF5: 0 | AG5: 0 | AH5: 0 | AI5: 0 | AJ5: 12000 | AK5: 0 | AL5: 0 | AM5: =SUM(H5:AL5) -> 64100 | AN5: =AVERAGE(H5:AK5) -> 2136.6667 | AO5: =AM5*8.5% -> 5448.5
A6: Alison Rodrigues da Silva SA | B6: 038.829.351-97 | C6: REN-1I09 | D6: GZV-9G76 | E6: EOE-3B10 | F6: (61) 99980-1995 | G6: Rodotrem Graneleiro | H6: 0 | I6: 0 | J6: 0 | K6: 0 | L6: 0 | M6: 31281.1 | N6: 0 | O6: 0 | P6: 0 | Q6: 0 | R6: 0 | S6: 0 | T6: 0 | U6: 0 | V6: 0 | W6: 0 | X6: 0 | Y6: 0 | Z6: 0 | AA6: 0 | AB6: 0 | AC6: 0 | AD6: 0 | AE6: 0 | AF6: 0 | AG6: 0 | AH6: 0 | AI6: 27522.15 | AJ6: 0 | AK6: 0 | AL6: 0 | AM6: =SUM(H6:AL6) -> 58803.25 | AN6: =AVERAGE(H6:AK6) -> 1960.1083 | AO6: =AM6*8.5% -> 4998.2763
A7: Renato de Jesus Souza | B7: 021.156.911-99 | C7: SDG-3C21 | D7: PAE-9952 | E7: PAE-9953 | F7: (61) 99648-6312 | G7: Rodotrem Graneleiro | H7: 0 | I7: 0 | J7: 0 | K7: 0 | L7: 0 | M7: 0 | N7: 5199.31 | O7: 0 | P7: 0 | Q7: 0 | R7: 0 | S7: 0 | T7: 6694.31 | U7: 0 | V7: 6726.87 | W7: 0 | X7: 0 | Y7: 0 | Z7: 0 | AA7: 6694.31 | AB7: 0 | AC7: 0 | AD7: 6726.87 | AE7: 0 | AF7: 0 | AG7: 0 | AH7: 0 | AI7: 6875 | AJ7: 0 | AK7: 6666.67 | AL7: 0 | AM7: =SUM(H7:AL7) -> 45583.34 | AN7: =AVERAGE(H7:AK7) -> 1519.4447 | AO7: =AM7*8.5% -> 3874.5839
A8: Arthur de Almeida Mascarenhas | B8: 044.559.691-01 | C8: SDA-2H39 | D8: AXH-2C39 | E8: AXH-2C40 | F8: (61) 99447-6996 | G8: Rodotrem Graneleiro | H8: 0 | I8: 0 | J8: 0 | K8: 0 | L8: 0 | M8: 0 | N8: 0 | O8: 23072 | P8: 0 | Q8: 0 | R8: 0 | S8: 0 | T8: 0 | U8: 6694.31 | V8: 6726.87 | W8: 0 | X8: 0 | Y8: 0 | Z8: 0 | AA8: 6694.31 | AB8: 0 | AC8: 6726.87 | AD8: 0 | AE8: 32960 | AF8: 0 | AG8: 0 | AH8: 0 | AI8: 0 | AJ8: 0 | AK8: 0 | AL8: 18180 | AM8: =SUM(H8:AL8) -> 101054.36 | AN8: =AVERAGE(H8:AK8) -> 2762.4787 | AO8: =AM8*8.5% -> 8589.6206
A9: Carlos Sebastião Oliveira da Silva | B9: 074.632.254-29 | C9: TFZ-9E59 | D9: HOF-5G14 | E9: HOF-5G10 | F9: (62) 99665-9462 | G9: Rodotrem Graneleiro | H9: 6328.57 | I9: 0 | J9: 0 | K9: 0 | L9: 0 | M9: 0 | N9: 0 | O9: 6694.31 | P9: 6726.87 | Q9: 0 | R9: 6694.31 | S9: 0 | T9: 0 | U9: 6726.86 | V9: 0 | W9: 6694.31 | X9: 6726.86 | Y9: 0 | Z9: 0 | AA9: 0 | AB9: 0 | AC9: 32960 | AD9: 0 | AE9: 0 | AF9: 0 | AG9: 0 | AH9: 0 | AI9: 0 | AJ9: 0 | AK9: 18180 | AL9: 0 | AM9: =SUM(H9:AL9) -> 97732.09 | AN9: =AVERAGE(H9:AK9) -> 3257.7363 | AO9: =AM9*8.5% -> 8307.2277
A10: Cristiano Martins da Silva | B10: 024.251.321-20 | C10: RVQ-1J85 | D10: PRW-8G54 | E10: PRW-8G64 | F10: (61) 99426-8741 | G10: Rodotrem Graneleiro | H10: 20160 | I10: 0 | J10: 0 | K10: 0 | L10: 0 | M10: 0 | N10: 0 | O10: 0 | P10: 0 | Q10: 24000 | R10: 0 | S10: 0 | T10: 0 | U10: 0 | V10: 0 | W10: 0 | X10: 0 | Y10: 0 | Z10: 0 | AA10: 31373.8 | AB10: 0 | AC10: 0 | AD10: 0 | AE10: 0 | AF10: 25600 | AG10: 0 | AH10: 0 | AI10: 0 | AJ10: 0 | AK10: 0 | AL10: 0 | AM10: =SUM(H10:AL10) -> 101133.8 | AN10: =AVERAGE(H10:AK10) -> 3371.1267 | AO10: =AM10*8.5% -> 8596.373
A11: Edvan Pereira Soares | B11: 863.646.421-87 | C11: RBL9C93 | D11: MFT-6623 | E11: ONS-7G44 | F11: (62) 99152-8240 | G11: Rodotrem Graneleiro | H11: 0 | I11: 0 | J11: 0 | K11: 0 | L11: 0 | M11: 0 | N11: 0 | O11: 0 | P11: 0 | Q11: 24000 | R11: 0 | S11: 0 | T11: 0 | U11: 0 | V11: 0 | W11: 0 | X11: 31425.31 | Y11: 0 | Z11: 0 | AA11: 0 | AB11: 0 | AC11: 0 | AD11: 0 | AE11: 0 | AF11: 0 | AG11: 0 | AH11: 0 | AI11: 0 | AJ11: 24000 | AK11: 0 | AL11: 0 | AM11: =SUM(H11:AL11) -> 79425.31 | AN11: =AVERAGE(H11:AK11) -> 2647.5103 | AO11: =AM11*8.5% -> 6751.1514
A12: Paulo Machado dos Santos | B12: 291.458.131-91 | C12: RCD7D72 | D12: OOC-7A05 | E12: OOB-7A05 | F12: (62) 99502-8337 | G12: Rodotrem Graneleiro | H12: 0 | I12: 6994.31 | J12: 0 | K12: 0 | L12: 0 | M12: 6994.31 | N12: 0 | O12: 0 | P12: 6726.87 | Q12: 0 | R12: 6694.31 | S12: 0 | T12: 6726.88 | U12: 0 | V12: 6694.31 | W12: 0 | X12: 6726.87 | Y12: 0 | Z12: 0 | AA12: 6694.31 | AB12: 6726.87 | AC12: 0 | AD12: 0 | AE12: 6875 | AF12: 0 | AG12: 0 | AH12: 6666.67 | AI12: 0 | AJ12: 6875 | AK12: 0 | AL12: 6666.67 | AM12: =SUM(H12:AL12) -> 88062.38 | AN12: =AVERAGE(H12:AK12) -> 2713.1903 | AO12: =AM12*8.5% -> 7485.3023
A13: Flavio Paiva dos Santos | B13: 036.626.214-95 | D13: PRY-0A53 | E13: PRX-7J53 | F13: (61) 98458-6062 | G13: Rodotrem Graneleiro | H13: 0 | I13: 0 | J13: 0 | K13: 6726.88 | L13: 0 | M13: 0 | N13: 0 | O13: 0 | P13: 0 | Q13: 0 | R13: 0 | S13: 0 | T13: 0 | U13: 0 | V13: 0 | W13: 0 | X13: 0 | Y13: 0 | Z13: 0 | AA13: 0 | AB13: 0 | AC13: 0 | AD13: 0 | AE13: 0 | AF13: 0 | AG13: 0 | AH13: 0 | AI13: 0 | AJ13: 0 | AK13: 0 | AL13: 0 | AM13: =SUM(H13:AL13) -> 6726.88 | AN13: =AVERAGE(H13:AK13) -> 224.22933 | AO13: =AM13*8.5% -> 571.7848
A14: Gilmar Lemes Moreira | B14: 331.607.241-15 | C14: RSA - 6F17 | D14: MKQ-9H98 | E14: MKQ-9D98 | F14: (61) 98322-8230 | G14: Rodotrem Graneleiro | H14: 0 | I14: 0 | J14: 0 | K14: 24000 | L14: 0 | M14: 0 | N14: 0 | O14: 0 | P14: 0 | Q14: 31301.7 | R14: 0 | S14: 0 | T14: 0 | U14: 0 | V14: 0 | W14: 0 | X14: 0 | Y14: 12500 | Z14: 0 | AA14: 0 | AB14: 0 | AC14: 0 | AD14: 0 | AE14: 0 | AF14: 0 | AG14: 0 | AH14: 23900 | AI14: 0 | AJ14: 0 | AK14: 0 | AL14: 0 | AM14: =SUM(H14:AL14) -> 91701.7 | AN14: =AVERAGE(H14:AK14) -> 3056.7233 | AO14: =AM14*8.5% -> 7794.6445
A15: Samuel dos Santos Leite | B15: 705.852.401-75 | C15: REO-5A75 | D15: REK-9E31 | E15: REK-9E32 | F15: (62) 98520-5053 | G15: Rodotrem Graneleiro | H15: 4817.88 | I15: 0 | J15: 0 | K15: 0 | L15: 0 | M15: 0 | N15: 5096.17 | O15: 0 | P15: 5117.88 | Q15: 0 | R15: 0 | S15: 0 | T15: 0 | U15: 0 | V15: 0 | W15: 5096.17 | X15: 0 | Y15: 5117.88 | Z15: 0 | AA15: 0 | AB15: 0 | AC15: 0 | AD15: 0 | AE15: 0 | AF15: 5095.34 | AG15: 0 | AH15: 0 | AI15: 0 | AJ15: 5117.88 | AK15: 0 | AL15: 0 | AM15: =SUM(H15:AL15) -> 35459.2 | AN15: =AVERAGE(H15:AK15) -> 1181.9733 | AO15: =AM15*8.5% -> 3014.032
A16: Irley Alberto Silva Souza | B16: 016.615.751-10 | D16: RBS-5J93 | E16: RBS-6A43 | F16: (61) 99257-7216 | G16: Rodotrem Graneleiro | H16: 0 | I16: 0 | J16: 0 | K16: 16000 | L16: 0 | M16: 0 | N16: 0 | O16: 0 | P16: 16000 | Q16: 0 | R16: 0 | S16: 0 | T16: 16000 | U16: 0 | V16: 0 | W16: 0 | X16: 0 | Y16: 0 | Z16: 0 | AA16: 0 | AB16: 0 | AC16: 0 | AD16: 0 | AE16: 0 | AF16: 0 | AG16: 0 | AH16: 0 | AI16: 0 | AJ16: 0 | AK16: 0 | AL16: 0 | AM16: =SUM(H16:AL16) -> 48000 | AN16: =AVERAGE(H16:AK16) -> 1600 | AO16: =AM16*8.5% -> 4080
A17: Jariel Ferreira Lima | B17: 006.344.131-47 | C17: SDO-1A48 | D17: GAJ-0D53 | E17: GKF-1B94 | F17: (61) 99822-2661 | G17: Rodotrem Sider | H17: 0 | I17: 0 | J17: 0 | K17: 0 | L17: 0 | M17: 0 | N17: 0 | O17: 0 | P17: 0 | Q17: 0 | R17: 0 | S17: 0 | T17: 18759.87 | U17: 0 | V17: 0 | W17: 0 | X17: 0 | Y17: 0 | Z17: 0 | AA17: 0 | AB17: 0 | AC17: 6328.57 | AD17: 0 | AE17: 44921.52 | AF17: 0 | AG17: 0 | AH17: 0 | AI17: 0 | AJ17: 0 | AK17: 0 | AL17: 17742.32 | AM17: =SUM(H17:AL17) -> 87752.28 | AN17: =AVERAGE(H17:AK17) -> 2333.6653 | AO17: =AM17*8.5% -> 7458.9438
A18: Jose Junho Ferreira | B18: 024.626.833-64 | C18: SDG-3C81 | D18: QTR-6809 | E18: RBK-7E38 | F18: (61) 99994-7737 | G18: Rodotrem Sider | H18: 0 | I18: 0 | J18: 0 | K18: 0 | L18: 0 | M18: 0 | N18: 23200 | O18: 0 | P18: 0 | Q18: 0 | R18: 6672.57 | S18: 0 | T18: 0 | U18: 31445.9 | V18: 0 | W18: 0 | X18: 0 | Y18: 0 | Z18: 0 | AA18: 0 | AB18: 0 | AC18: 24600 | AD18: 0 | AE18: 0 | AF18: 0 | AG18: 0 | AH18: 0 | AI18: 0 | AJ18: 0 | AK18: 0 | AL18: 0 | AM18: =SUM(H18:AL18) -> 85918.47 | AN18: =AVERAGE(H18:AK18) -> 2863.949 | AO18: =AM18*8.5% -> 7303.07
A19: Julio Cesar Padilha Simoes | B19: 056.869.581-06 | C19: RCC7E22 | D19: RBU - 7B44 | E19: RBU - 7D14 | F19: (61) 98185-5916 | G19: Rodotrem Sider | H19: 23900 | I19: 0 | J19: 0 | K19: 0 | L19: 0 | M19: 0 | N19: 0 | O19: 0 | P19: 0 | Q19: 0 | R19: 0 | S19: 0 | T19: 0 | U19: 0 | V19: 0 | W19: 0 | X19: 13820.12 | Y19: 0 | Z19: 0 | AA19: 0 | AB19: 0 | AC19: 0 | AD19: 0 | AE19: 0 | AF19: 0 | AG19: 0 | AH19: 24607 | AI19: 0 | AJ19: 0 | AK19: 0 | AL19: 0 | AM19: =SUM(H19:AL19) -> 62327.12 | AN19: =AVERAGE(H19:AK19) -> 2077.5707 | AO19: =AM19*8.5% -> 5297.8052
A20: Kelson Castro Chaves | B20: 857.120.191-91 | C20: RCM-1H95 | D20: FPT-0G91 | E20: GDX-5B62 | F20: (61) 99292-1292 | G20: Rodotrem Sider | H20: 0 | I20: 0 | J20: 0 | K20: 0 | L20: 0 | M20: 0 | N20: 0 | O20: 13861.56 | P20: 0 | Q20: 0 | R20: 0 | S20: 0 | T20: 0 | U20: 6694.31 | V20: 0 | W20: 44368.56 | X20: 0 | Y20: 0 | Z20: 0 | AA20: 0 | AB20: 21126.7 | AC20: 0 | AD20: 0 | AE20: 0 | AF20: 0 | AG20: 0 | AH20: 0 | AI20: 0 | AJ20: 6875 | AK20: 0 | AL20: 44921.52 | AM20: =SUM(H20:AL20) -> 137847.65 | AN20: =AVERAGE(H20:AK20) -> 3097.5377 | AO20: =AM20*8.5% -> 11717.05
A21: Lucas Carvalho Pereira | B21: 020.530.081-21 | C21: TFP-2E23 | D21: GDI-4D01 | E21: FMP-9E71 | F21: (61) 99869-6347 | G21: Rodotrem Sider | H21: 0 | I21: 0 | J21: 0 | K21: 0 | L21: 0 | M21: 0 | N21: 16000 | O21: 0 | P21: 0 | Q21: 0 | R21: 16000 | S21: 0 | T21: 12000 | U21: 0 | V21: 16000 | W21: 0 | X21: 0 | Y21: 0 | Z21: 0 | AA21: 0 | AB21: 33000 | AC21: 0 | AD21: 0 | AE21: 0 | AF21: 0 | AG21: 0 | AH21: 0 | AI21: 0 | AJ21: 0 | AK21: 0 | AL21: 17000 | AM21: =SUM(H21:AL21) -> 110000 | AN21: =AVERAGE(H21:AK21) -> 3100 | AO21: =AM21*8.5% -> 9350
A22: Luciano Quintanilha Gomes | B22: 078.590.297-07 | C22: TFQ-0J19 | D22: RBM - 3G03 | E22: RBM - 3F93 | F22: (62) 98157-6973 | G22: Rodotrem Sider | H22: 0 | I22: 0 | J22: 0 | K22: 16000 | L22: 0 | M22: 0 | N22: 0 | O22: 0 | P22: 6694.31 | Q22: 0 | R22: 6726.87 | S22: 0 | T22: 0 | U22: 6694.31 | V22: 0 | W22: 6726.87 | X22: 0 | Y22: 32960 | Z22: 0 | AA22: 0 | AB22: 0 | AC22: 0 | AD22: 22360 | AE22: 0 | AF22: 0 | AG22: 0 | AH22: 0 | AI22: 0 | AJ22: 0 | AK22: 0 | AL22: 0 | AM22: =SUM(H22:AL22) -> 98162.36 | AN22: =AVERAGE(H22:AK22) -> 3272.0787 | AO22: =AM22*8.5% -> 8343.8006
A23: Luiz Claudio Pessoa | B23: 442.761.411-68 | C23: PRP-7B62 | D23: RBN-3H25 | E23: RBN-3H75 | F23: (61) 99696-0881 | G23: Rodotrem Sider | H23: 22560 | I23: 0 | J23: 0 | K23: 0 | L23: 0 | M23: 0 | N23: 24600 | O23: 0 | P23: 0 | Q23: 0 | R23: 0 | S23: 0 | T23: 0 | U23: 0 | V23: 0 | W23: 0 | X23: 21500 | Y23: 0 | Z23: 0 | AA23: 0 | AB23: 0 | AC23: 24000 | AD23: 0 | AE23: 0 | AF23: 0 | AG23: 0 | AH23: 0 | AI23: 0 | AJ23: 0 | AK23: 0 | AL23: 34537.7 | AM23: =SUM(H23:AL23) -> 127197.7 | AN23: =AVERAGE(H23:AK23) -> 3088.6667 | AO23: =AM23*8.5% -> 10811.805
A24: Luiz Ricardo Melo de Almeida | B24: 040.411.491-18 | C24: SDG-1G91 | D24: RBW-0G43 | E24: RBV-7H23 | F24: (61) 99191-6324 | G24: Rodotrem Sider | H24: 0 | I24: 0 | J24: 0 | K24: 0 | L24: 0 | M24: 19050 | N24: 0 | O24: 0 | P24: 0 | Q24: 17600 | R24: 0 | S24: 0 | T24: 16000 | U24: 0 | V24: 0 | W24: 0 | X24: 0 | Y24: 0 | Z24: 0 | AA24: 0 | AB24: 6694.31 | AC24: 0 | AD24: 44921.52 | AE24: 0 | AF24: 0 | AG24: 0 | AH24: 0 | AI24: 0 | AJ24: 0 | AK24: 19584.1 | AL24: 0 | AM24: =SUM(H24:AL24) -> 123849.93 | AN24: =AVERAGE(H24:AK24) -> 4128.331 | AO24: =AM24*8.5% -> 10527.244
A25: Marcelo Silva Sousa | B25: 783.744.211-34 | D25: QTO-1298 | E25: QTO-1088 | F25: (61) 99317-3916 | G25: Rodotrem Sider | H25: 0 | I25: 0 | J25: 0 | K25: 0 | L25: 0 | M25: 0 | N25: 0 | O25: 0 | P25: 0 | Q25: 0 | R25: 0 | S25: 0 | T25: 16965 | U25: 0 | V25: 0 | W25: 0 | X25: 0 | Y25: 0 | Z25: 0 | AA25: 0 | AB25: 0 | AC25: 0 | AD25: 0 | AE25: 0 | AF25: 0 | AG25: 0 | AH25: 0 | AI25: 0 | AJ25: 0 | AK25: 0 | AL25: 0 | AM25: =SUM(H25:AL25) -> 16965 | AN25: =AVERAGE(H25:AK25) -> 565.5 | AO25: =AM25*8.5% -> 1442.025
A26: Fabrício Bernadino de Brito | B26: 079.915.486-51 | D26: SDJ-7C68 | E26: SCJ-1J98 | F26: (61) 99908-5809 | G26: Rodotrem Sider | H26: 12000 | I26: 0 | J26: 20000 | K26: 0 | L26: 0 | M26: 0 | N26: 0 | O26: 12000 | P26: 0 | Q26: 0 | R26: 20000 | S26: 0 | T26: 0 | U26: 0 | V26: 0 | W26: 0 | X26: 0 | Y26: 0 | Z26: 0 | AA26: 0 | AB26: 0 | AC26: 0 | AD26: 0 | AE26: 0 | AF26: 0 | AG26: 0 | AH26: 0 | AI26: 0 | AJ26: 0 | AK26: 0 | AM26: =SUM(H26:AL26) -> 64000 | AN26: =AVERAGE(H26:AK26) -> 2133.3333 | AO26: =AM26*8.5% -> 5440
A27: Marcos Antonio Martins | B27: 599.872.431-34 | C27: SDL-5J68 | D27: RBR-2G14 | E27: RBR-2G44 | F27: (61) 99867-1574 | G27: Rodotrem Sider | H27: 0 | I27: 0 | J27: 0 | K27: 0 | L27: 0 | M27: 0 | N27: 0 | O27: 0 | P27: 0 | Q27: 0 | R27: 0 | S27: 0 | T27: 0 | U27: 0 | V27: 13757.6 | W27: 0 | X27: 0 | Y27: 0 | Z27: 0 | AA27: 0 | AB27: 33557.02 | AC27: 0 | AD27: 0 | AE27: 0 | AF27: 0 | AG27: 0 | AH27: 0 | AI27: 0 | AJ27: 0 | AK27: 0 | AL27: 20215 | AM27: =SUM(H27:AL27) -> 67529.62 | AN27: =AVERAGE(H27:AK27) -> 1577.154 | AO27: =AM27*8.5% -> 5740.0177
A28: Mauro Batista de Lima | B28: 413.502.865-91 | C28: RBX-5F42 | D28: FJH-7E96 | E28: GFR-0J56 | F28: (61) 99310-4960 | G28: Rodotrem Sider | H28: 0 | I28: 0 | J28: 6672.56 | K28: 0 | L28: 0 | M28: 0 | N28: 0 | O28: 0 | P28: 0 | Q28: 44368.56 | R28: 0 | S28: 0 | T28: 0 | U28: 0 | V28: 0 | W28: 0 | X28: 0 | Y28: 0 | Z28: 0 | AA28: 0 | AB28: 0 | AC28: 0 | AD28: 24000 | AE28: 0 | AF28: 0 | AG28: 0 | AH28: 0 | AI28: 0 | AJ28: 0 | AK28: 0 | AL28: 18940 | AM28: =SUM(H28:AL28) -> 93981.12 | AN28: =AVERAGE(H28:AK28) -> 2501.3707 | AO28: =AM28*8.5% -> 7988.3952
A29: Murilo Costa Silva | B29: 003.132.941-19 | C29: RVS-9J69 | D29: TFA-8C71 | E29: TFQ-8F21 | F29: (61) 98206-4412 | G29: Rodotrem Sider | H29: 0 | I29: 0 | J29: 12705.74 | K29: 0 | L29: 0 | M29: 0 | N29: 0 | O29: 6694.31 | P29: 0 | Q29: 44921.12 | R29: 0 | S29: 0 | T29: 0 | U29: 0 | V29: 0 | W29: 0 | X29: 19059.87 | Y29: 0 | Z29: 0 | AA29: 0 | AB29: 0 | AC29: 0 | AD29: 13000 | AE29: 20000 | AF29: 0 | AG29: 0 | AH29: 0 | AI29: 0 | AJ29: 0 | AK29: 0 | AL29: 0 | AM29: =SUM(H29:AL29) -> 116381.04 | AN29: =AVERAGE(H29:AK29) -> 3879.368 | AO29: =AM29*8.5% -> 9892.3884
A30: Ralisson Duarte de Souza | B30: 896.342.411-15 | C30: QUJ-5G26 | D30: GJR-6I44 | E30: GHL-8I33 | F30: (61) 99946-8725 | G30: Rodotrem Sider | H30: 0 | I30: 0 | J30: 0 | K30: 0 | L30: 0 | M30: 0 | N30: 0 | O30: 0 | P30: 0 | Q30: 0 | R30: 0 | S30: 0 | T30: 0 | U30: 17300 | V30: 0 | W30: 0 | X30: 0 | Y30: 0 | Z30: 0 | AA30: 0 | AB30: 0 | AC30: 16125 | AD30: 0 | AE30: 0 | AF30: 0 | AG30: 0 | AH30: 0 | AI30: 17700 | AJ30: 0 | AK30: 0 | AL30: 0 | AM30: =SUM(H30:AL30) -> 51125 | AN30: =AVERAGE(H30:AK30) -> 1704.1667 | AO30: =AM30*8.5% -> 4345.625
A31: Railandher Nunes dos Santos | B31: 064.769-571-55 | D31: SCT-8F58 | E31: SDH-8D38 | F31: (61) 99562-5503 | G31: Rodotrem Sider | H31: 0 | I31: 0 | J31: 31409.85 | K31: 0 | L31: 0 | M31: 0 | N31: 0 | O31: 0 | P31: 0 | Q31: 0 | R31: 0 | S31: 0 | T31: 24600 | U31: 0 | V31: 0 | W31: 0 | X31: 0 | Y31: 0 | Z31: 0 | AA31: 0 | AB31: 0 | AC31: 0 | AD31: 0 | AE31: 0 | AF31: 0 | AG31: 0 | AH31: 0 | AI31: 0 | AJ31: 0 | AK31: 0 | AL31: 0 | AM31: =SUM(H31:AL31) -> 56009.85 | AN31: =AVERAGE(H31:AK31) -> 1866.995 | AO31: =AM31*8.5% -> 4760.8373
A32: Ronaldo Duarte | B32: 954.452.421-53 | C32: JBE-1E97 | D32: GHB-7F27 | E32: XXXXXX | F32: (61) 98416-2357 | G32: LS Sider | H32: 0 | I32: 0 | J32: 0 | K32: 0 | L32: 0 | M32: 0 | N32: 0 | O32: 0 | P32: 0 | Q32: 0 | R32: 0 | S32: 0 | T32: 0 | U32: 6600 | V32: 0 | W32: 0 | X32: 0 | Y32: 0 | Z32: 0 | AA32: 14393 | AB32: 0 | AC32: 0 | AD32: 24872.35 | AE32: 0 | AF32: 0 | AG32: 0 | AH32: 0 | AI32: 0 | AJ32: 0 | AK32: 0 | AL32: 11909.4 | AM32: =SUM(H32:AL32) -> 57774.75 | AN32: =AVERAGE(H32:AK32) -> 1528.845 | AO32: =AM32*8.5% -> 4910.8538
A33: Valmir de Souza Santos | B33: 649.462.151-15 | C33: TFY-6F22 | D33: DJV-1A46 | E33: XXXXXX | F33: (61) 99994-1121 | G33: LS Sider | H33: 0 | I33: 44921.12 | J33: 0 | K33: 0 | L33: 0 | M33: 0 | N33: 0 | O33: 0 | P33: 0 | Q33: 15960 | R33: 0 | S33: 0 | T33: 0 | U33: 0 | V33: 6694.31 | W33: 0 | X33: 44921.52 | Y33: 0 | Z33: 0 | AA33: 0 | AB33: 0 | AC33: 0 | AD33: 0 | AE33: 18495 | AF33: 0 | AG33: 0 | AH33: 0 | AI33: 0 | AJ33: 0 | AK33: 0 | AL33: 40868.66 | AM33: =SUM(H33:AL33) -> 171860.61 | AN33: =AVERAGE(H33:AK33) -> 4366.3983 | AO33: =AM33*8.5% -> 14608.152
A34: Weslen Barbosa Rezende | B34: 701.419.591-34 | C34: REK0D67 | AD34: 31409.85 | AK34: 24000 | AM34: =SUM(H34:AL34) -> 55409.85 | AN34: =AVERAGE(H34:AK34) -> 27704.925 | AO34: =AM34*8.5% -> 4709.8373
A35: Maicon Alves dos Santos Silva | B35: 029..865.001-02 | C35: RCD5C48 | D35: RCA-5G48 | E35: XXXXXX | F35: (61) 98186-8698 | G35: Graneleiro | H35: 0 | I35: 0 | J35: 0 | K35: 0 | L35: 0 | M35: 0 | N35: 0 | O35: 0 | P35: 0 | Q35: 0 | R35: 0 | S35: 0 | T35: 0 | U35: 0 | V35: 0 | W35: 0 | X35: 0 | Y35: 0 | Z35: 0 | AA35: 0 | AB35: 0 | AC35: 0 | AD35: 0 | AE35: 0 | AF35: 0 | AG35: 0 | AH35: 0 | AI35: 30312 | AJ35: 0 | AK35: 0 | AL35: 0 | AM35: =SUM(H35:AL35) -> 30312 | AN35: =AVERAGE(H35:AK35) -> 1010.4 | AO35: =AM35*8.5% -> 2576.52
A36: MANUTENÇÃO | C36: RCE-0I83 | AM36: =SUM(H36:AL36) -> 0 | AN36: =AVERAGE(H36:AK36) -> #DIV/0! | AO36: =AM36*8.5% -> 0
A37: MANUTENÇÃO | C37: SDH-1G58 | AM37: =SUM(H37:AL37) -> 0 | AN37: =AVERAGE(H37:AK37) -> #DIV/0! | AO37: =AM37*8.5% -> 0
A38: MANUTENÇÃO | C38: RBL4E27 | AM38: =SUM(H38:AL38) -> 0 | AN38: =AVERAGE(H38:AK38) -> #DIV/0! | AO38: =AM38*8.5% -> 0
A39: MANUTENÇÃO | C39: FSI - 2I68 | AM39: =SUM(H39:AL39) -> 0 | AN39: =AVERAGE(H39:AK39) -> #DIV/0! | AO39: =AM39*8.5% -> 0
A40: Missias Alves Pereira | B40: 539.272.491-49 | C40: TFK5A29 | AG40: 34154.11 | AM40: =SUM(H40:AL40) -> 34154.11 | AN40: =AVERAGE(H40:AK40) -> 34154.11 | AO40: =AM40*8.5% -> 2903.0994
A41: Hometeck | H41: 0 | I41: 2116.63 | J41: 0 | K41: 0 | L41: 0 | M41: 0 | O41: 0 | P41: 0 | Q41: 0 | R41: 2629.8 | S41: 0 | T41: 0 | U41: 0 | V41: 2629.8 | W41: 0 | X41: 0 | Y41: 2629.8 | Z41: 0 | AA41: 0 | AB41: 0 | AC41: 0 | AD41: 0 | AE41: 0 | AF41: 0 | AG41: 0 | AH41: 0 | AI41: 0 | AJ41: 0 | AK41: 0 | AL41: 0 | AM41: =SUM(H41:AL41) -> 10006.03 | AN41: =AVERAGE(H41:AK41) -> 345.03552 | AO41: =AM41*8.5% -> 850.51255
C42: DIA | H42: =SUM(H5:H35) -> 89766.45 | I42: =SUM(I5:I41) -> 54032.06 | J42: =SUM(J5:J35) -> 70788.15 | K42: =SUM(K5:K35) -> 62726.88 | L42: =SUM(L5:L41) -> 0 | M42: =SUM(M5:M41) -> 57325.41 | N42: =SUM(N5:N41) -> 74095.48 | O42: =SUM(O5:O41) -> 62322.18 | P42: =SUM(P5:P41) -> 41265.93 | Q42: =SUM(Q5:Q41) -> 202151.38 | R42: =SUM(R5:R41) -> 65417.86 | S42: =SUM(S5:S41) -> 0 | T42: =SUM(T5:T41) -> 117746.06 | U42: =SUM(U5:U35) -> 118255.69 | V42: =SUM(V5:V41) -> 59229.76 | W42: =SUM(W5:W35) -> 62885.91 | X42: =SUM(X5:X35) -> 144180.55 | Y42: =SUM(Y5:Y41) -> 53207.68 | Z42: =SUM(Z5:Z35) -> 0 | AA42: =SUM(AA5:AA35) -> 65849.73 | AB42: =SUM(AB5:AB35) -> 101104.9 | AC42: =SUM(AC5:AC35) -> 110740.44 | AD42: =SUM(AD5:AD35) -> 167290.59 | AE42: =SUM(AE5:AE41) -> 139251.52 | AF42: =SUM(AF5:AF35) -> 30695.34 | AG42: =SUM(AG5:AG41) -> 34154.11 | AH42: =SUM(AH5:AH35) -> 55173.67 | AI42: =SUM(AI5:AI35) -> 82409.15 | AJ42: =SUM(AJ5:AJ35) -> 54867.88 | AK42: =SUM(AK5:AK35) -> 68430.77 | AL42: =SUM(AL5:AL35) -> 230981.27 | AM42: =SUM(H42:AL42) -> 2476346.8 | AN42: =SUM(AN5:AN35) -> 99231.443 | AO42: =SUM(AO5:AO35) -> 206735.87
H43: 45931 | I43: 45932 | J43: 45933 | K43: 45934 | L43: 45935 | M43: 45936 | N43: 45937 | O43: 45938 | P43: 45939 | Q43: 45940 | R43: 45941 | S43: 45942 | T43: 45943 | U43: 45944 | V43: 45945 | W43: 45946 | X43: 45947 | Y43: 45948 | Z43: 45949 | AA43: 45950 | AB43: 45951 | AC43: 45952 | AD43: 45953 | AE43: 45954 | AF43: 45955 | AG43: 45956 | AH43: 45957 | AI43: 45958 | AJ43: 45959 | AK43: 45960 | AL43: 45961

Sheet NOVEMBRO 
C4: GESTÃO A VISTA DO RESULTADO DURANTE O MÊS VIGENTE
C6: QTD | D6: VEICULO | E6: META MÊS | G6: PRODUÇÃO
C7: 4 | D7: LS | E7: 70000 | G7: =E7*C7 -> 280000
C8: 27 | D8: RODOTREM | E8: 100000 | G8: =E8*C8 -> 2700000
E9: TOTAL | G9: =SUM(G7:G8) -> 2980000
G11: DIGITAR
